Workbook

Sheet Summary
F2: Most-likely | G2: Face value
F3: Optimistic | G3: Might take lesser effort
F4: Pessimistic | G4: Might take more effort
F5: Calculated Man-Days | G5: Calibrated estimate
B6: MAN-DAYS
E7: ="50%" -> 50% | F7: ="10%" -> 10%
B8: # of Epics | C8: Product | D8: Most-likely Man-days | E8: ="Optimistic Man-days ("&E7&")" -> Optimistic Man-days (50%) | F8: ="Pessimistic ("& F7&")" -> Pessimistic (10%) | G8: Calculated Man-Days | H8: TK Approved
B9: =COUNTA('OmniConnect RMI'!D:D) -> 51 | C9: OmniConnect | D9: =SUM('OmniConnect RMI'!V:V) -> 810 | E9: =SUM('OmniConnect RMI'!W:W) -> 405 | F9: =SUM('OmniConnect RMI'!X:X) -> 1012.5 | G9: =SUM('OmniConnect RMI'!Y:Y) -> 776.25 | H9: =G9/2 -> 388.125
B10: =COUNTA('Fintech Fuel RMI'!D:D) -> 54 | C10: Fintech Fuel | D10: =SUM('Fintech Fuel RMI'!V:V) -> 1210 | E10: =SUM('Fintech Fuel RMI'!W:W) -> 605 | F10: =SUM('Fintech Fuel RMI'!X:X) -> 1331 | G10: =SUM('Fintech Fuel RMI'!Y:Y) -> 1129.3333 | H10: =G10/2 -> 564.66667
B11: =COUNTA('OmniChat RMI'!D:D) -> 14 | C11: OmniChat | D11: =SUM('OmniChat RMI'!V:V) -> 413 | E11: =SUM('OmniChat RMI'!W:W) -> 206.5 | F11: =SUM('OmniChat RMI'!X:X) -> 454.3 | G11: =SUM('OmniChat RMI'!Y:Y) -> 400.46667 | H11: =G11/2 -> 200.23333
B12: =COUNTA('Digital Log RMI'!D:D) -> 31 | C12: Digital Log | D12: =SUM('Digital Log RMI'!V:V) -> 972 | E12: =SUM('Digital Log RMI'!W:W) -> 486 | F12: =SUM('Digital Log RMI'!X:X) -> 1215 | G12: =SUM('Digital Log RMI'!Y:Y) -> 931.5 | H12: =G12/2 -> 465.75
C13: Support (3 person) | D13: 176 | E13: 88 | F13: 193.6 | G13: 164.26667 | H13: =G13 -> 164.26667
C14: Total | D14: =SUM(D9:D12,D13) -> 3581 | E14: =SUM(E9:E12,E13) -> 1790.5 | F14: =SUM(F9:F12,F13) -> 4206.4 | G14: =SUM(G9:G12,G13) -> 3401.8167 | H14: =SUM(H9:H12,H13) -> 1783.0417

Sheet OmniConnect RMI
A1: OmniConnect Roadmap Items | H1: BHW | I1: TK | J1: AA | K1: TS | M1: RnD Most likely | W1: TK Budgeted | AQ1: `=($Y3-($M3+$T3+$Q3)) * (SUBSTITUTE(MID(AH$2, SEARCH("(", AH$2) + 1, 5), "%)", "") / 100)
A2: Sr # | B2: Category | C2: Components | D2: Road Map Items | E2: Jira ID | F2: Originator | G2: Value | H2: Priority | I2: Priority | J2: Priority | K2: Priority | L2: Plan Status | M2: Prc Design | N2: R/URS | O2: R/DDS | P2: Dev | Q2: SQA | R2: Prc Test | S2: Doc | T2: Reg SQA | U2: Release | V2: Man Days | W2: ="Optimistic ("&Summary!E7&")" -> Optimistic (50%) | X2: Pessimistic (10%) | Y2: Est Formula | Z2: TK's TARGET | AA2: Start Date | AB2: Dev End | AC2: SQA HO | AD2: Prod Date | AE2: Prc Design | AF2: R/URS (5%) | AG2: R/DDS (10%) | AH2: Dev (40%) | AI2: Handover | AJ2: SQA (15%) | AK2: Bug Fixing (15%) | AL2: Prc Test | AM2: Doc (5%) | AN2: Reg SQA (10%) | AO2: Release
A3: 1 | B3: Input | C3: Streaming | D3: OC Streaming (80% done) | E3: https://octopusdtlsupport.atlassian.net/browse/O2-793 | F3: RnD | H3: 1 | K3: 1 | L3: Plan | N3: 2 | O3: 20 | P3: 40 | Q3: 20 | S3: 0 | T3: 2 | V3: =SUM(M3:U3) -> 84 | W3: =V3 - (V3 * (SUBSTITUTE(SUBSTITUTE($W$2, "Optimistic (", ""), "%)", "") / 100)) -> 42 | X3: =V3 + (W3 * (SUBSTITUTE(SUBSTITUTE($W$2, "Optimistic (", ""), "%)", "") / 100)) -> 105 | Y3: =(W3+(4*V3)+X3)/6 -> 80.5 | Z3: =Y3/2 -> 40.25 | AD3: =AC3+5 -> 5 | AE3: =IF($Z3="",0,IF($M3="",0,$M3)) -> 0 | AF3: =IF(OR($Z3="",$N3=""),0,$Z3*5%) -> 2.0125 | AG3: =IF(OR($Z3="",$O3=""),0,$Z3*10%) -> 4.025 | AH3: =IF($Z3="",0,IF(AND($P3="",$Q3=""),($Z3-$AE3-$AF3-$AG3-$AI3-$AK3-$AL3-$AM3-$AN3-$AO3),IF($P3="",0,IF($Q3="",($Z3-$AE3-$AF3-$AG3-$AI3-$AK3-$AL3-$AM3-$AN3-$AO3),($Z3-$AE3-$AF3-$AG3-$AI3-$AK3-$AL3-$AM3-$AN3-$AO3)*40%/(40%+15%))))) -> 15.736364 | AI3: =IF($Z3="",0,IF($P3="",0,0.5)) -> 0.5 | AJ3: =IF($Z3="",0,IF(AND($P3="",$Q3=""),0,IF($Q3="",0,IF($P3="",($Z3-$AE3-$AF3-$AG3-$AI3-$AK3-$AL3-$AM3-$AN3-$AO3),($Z3-$AE3-$AF3-$AG3-$AI3-$AK3-$AL3-$AM3-$AN3-$AO3)*15%/(40%+15%))))) -> 5.9011364 | AK3: =IF($Z3="",0,$Z3*15%) -> 6.0375 | AL3: =IF($Z3="",0,IF($R3="",0,$R3)) -> 0 | AM3: =IF(OR($Z3="",$S3=""),0,$Z3*5%) -> 2.0125 | AN3: =IF(OR($Z3="",$T3=""),0,$Z3*10%) -> 4.025 | AO3: =IF($Z3="",0,IF($U3="",0,$U3)) -> 0 | AP3: =SUM(AE3:AM3) -> 36.225
A4: 2 | D4: OC streaming on Pub Sub | F4: Imp Team | H4: 1 | K4: 1 | L4: UnPlan | V4: =SUM(M4:U4) -> 0 | W4: =V4 - (V4 * (SUBSTITUTE(SUBSTITUTE($W$2, "Optimistic (", ""), "%)", "") / 100)) -> 0 | X4: =V4 + (W4 * (SUBSTITUTE(SUBSTITUTE($W$2, "Optimistic (", ""), "%)", "") / 100)) -> 0 | Y4: =(W4+(4*V4)+X4)/6 -> 0 | Z4: =Y4/2 -> 0 | AE4: =IF($Z4="",0,IF($M4="",0,$M4)) -> 0 | AF4: =IF(OR($Z4="",$N4=""),0,$Z4*5%) -> 0 | AG4: =IF(OR($Z4="",$O4=""),0,$Z4*10%) -> 0 | AH4: =IF($Z4="",0,IF(AND($P4="",$Q4=""),($Z4-$AE4-$AF4-$AG4-$AI4-$AK4-$AL4-$AM4-$AN4-$AO4),IF($P4="",0,IF($Q4="",($Z4-$AE4-$AF4-$AG4-$AI4-$AK4-$AL4-$AM4-$AN4-$AO4),($Z4-$AE4-$AF4-$AG4-$AI4-$AK4-$AL4-$AM4-$AN4-$AO4)*40%/(40%+15%))))) -> 0 | AI4: =IF($Z4="",0,IF($P4="",0,0.5)) -> 0 | AJ4: =IF($Z4="",0,IF(AND($P4="",$Q4=""),0,IF($Q4="",0,IF($P4="",($Z4-$AE4-$AF4-$AG4-$AI4-$AK4-$AL4-$AM4-$AN4-$AO4),($Z4-$AE4-$AF4-$AG4-$AI4-$AK4-$AL4-$AM4-$AN4-$AO4)*15%/(40%+15%))))) -> 0 | AK4: =IF($Z4="",0,$Z4*15%) -> 0 | AL4: =IF($Z4="",0,IF($R4="",0,$R4)) -> 0 | AM4: =IF(OR($Z4="",$S4=""),0,$Z4*5%) -> 0 | AN4: =IF(OR($Z4="",$T4=""),0,$Z4*10%) -> 0 | AO4: =IF($Z4="",0,IF($U4="",0,$U4)) -> 0 | AP4: =SUM(AE4:AM4) -> 0
A5: 3 | C5: Bulk Device creation | D5: BULK DEVICE CREATION FOR NON SMART DEVICES (on hold, no further thought process undertaken) Current feature is to bulk create MQTT/IOT devices which has ability to directly connect to Azure IOT hub as an independent devices. It does not cover the schenario where multiple non smart devices are connected to one gateway from where the data is send to cloud. Now need is to replicate such non smart devices (connected to gateway) on OC as logical devices. | F5: Management | H5: 2 | K5: 2 | Q5: 5 | U5: 1 | V5: =SUM(M5:U5) -> 6 | W5: =V5 - (V5 * (SUBSTITUTE(SUBSTITUTE($W$2, "Optimistic (", ""), "%)", "") / 100)) -> 3 | X5: =V5 + (W5 * (SUBSTITUTE(SUBSTITUTE($W$2, "Optimistic (", ""), "%)", "") / 100)) -> 7.5 | Y5: =(W5+(4*V5)+X5)/6 -> 5.75 | Z5: =Y5/2 -> 2.875 | AE5: =IF($Z5="",0,IF($M5="",0,$M5)) -> 0 | AF5: =IF(OR($Z5="",$N5=""),0,$Z5*5%) -> 0 | AG5: =IF(OR($Z5="",$O5=""),0,$Z5*10%) -> 0 | AH5: =IF($Z5="",0,IF(AND($P5="",$Q5=""),($Z5-$AE5-$AF5-$AG5-$AI5-$AK5-$AL5-$AM5-$AN5-$AO5),IF($P5="",0,IF($Q5="",($Z5-$AE5-$AF5-$AG5-$AI5-$AK5-$AL5-$AM5-$AN5-$AO5),($Z5-$AE5-$AF5-$AG5-$AI5-$AK5-$AL5-$AM5-$AN5-$AO5)*40%/(40%+15%))))) -> 0 | AI5: =IF($Z5="",0,IF($P5="",0,0.5)) -> 0 | AJ5: =IF($Z5="",0,IF(AND($P5="",$Q5=""),0,IF($Q5="",0,IF($P5="",($Z5-$AE5-$AF5-$AG5-$AI5-$AK5-$AL5-$AM5-$AN5-$AO5),($Z5-$AE5-$AF5-$AG5-$AI5-$AK5-$AL5-$AM5-$AN5-$AO5)*15%/(40%+15%))))) -> 1.44375 | AK5: =IF($Z5="",0,$Z5*15%) -> 0.43125 | AL5: =IF($Z5="",0,IF($R5="",0,$R5)) -> 0 | AM5: =IF(OR($Z5="",$S5=""),0,$Z5*5%) -> 0 | AN5: =IF(OR($Z5="",$T5=""),0,$Z5*10%) -> 0 | AO5: =IF($Z5="",0,IF($U5="",0,$U5)) -> 1 | AP5: =SUM(AE5:AM5) -> 1.875
A6: 4 | C6: Import Site Layout | D6: Import Site Layout catchup till date | F6: RnD | H6: 2 | K6: 3 | L6: UnPlan | V6: =SUM(M6:U6) -> 0 | W6: =V6 - (V6 * (SUBSTITUTE(SUBSTITUTE($W$2, "Optimistic (", ""), "%)", "") / 100)) -> 0 | X6: =V6 + (W6 * (SUBSTITUTE(SUBSTITUTE($W$2, "Optimistic (", ""), "%)", "") / 100)) -> 0 | Y6: =(W6+(4*V6)+X6)/6 -> 0 | Z6: =Y6/2 -> 0 | AE6: =IF($Z6="",0,IF($M6="",0,$M6)) -> 0 | AF6: =IF(OR($Z6="",$N6=""),0,$Z6*5%) -> 0 | AG6: =IF(OR($Z6="",$O6=""),0,$Z6*10%) -> 0 | AH6: =IF($Z6="",0,IF(AND($P6="",$Q6=""),($Z6-$AE6-$AF6-$AG6-$AI6-$AK6-$AL6-$AM6-$AN6-$AO6),IF($P6="",0,IF($Q6="",($Z6-$AE6-$AF6-$AG6-$AI6-$AK6-$AL6-$AM6-$AN6-$AO6),($Z6-$AE6-$AF6-$AG6-$AI6-$AK6-$AL6-$AM6-$AN6-$AO6)*40%/(40%+15%))))) -> 0 | AI6: =IF($Z6="",0,IF($P6="",0,0.5)) -> 0 | AJ6: =IF($Z6="",0,IF(AND($P6="",$Q6=""),0,IF($Q6="",0,IF($P6="",($Z6-$AE6-$AF6-$AG6-$AI6-$AK6-$AL6-$AM6-$AN6-$AO6),($Z6-$AE6-$AF6-$AG6-$AI6-$AK6-$AL6-$AM6-$AN6-$AO6)*15%/(40%+15%))))) -> 0 | AK6: =IF($Z6="",0,$Z6*15%) -> 0 | AL6: =IF($Z6="",0,IF($R6="",0,$R6)) -> 0 | AM6: =IF(OR($Z6="",$S6=""),0,$Z6*5%) -> 0 | AN6: =IF(OR($Z6="",$T6=""),0,$Z6*10%) -> 0 | AO6: =IF($Z6="",0,IF($U6="",0,$U6)) -> 0 | AP6: =SUM(AE6:AM6) -> 0
A7: 5 | C7: Scheduled Pull | D7: Support for Wide tables from SQL Source | E7: https://octopusdtlsupport.atlassian.net/browse/O2-2188 | F7: RnD | K7: 2 | P7: =10+2 -> 12 | Q7: 2 | S7: 2 | T7: 5 | U7: =(10+2)/3 -> 4 | V7: =SUM(M7:U7) -> 25 | W7: =V7 - (V7 * (SUBSTITUTE(SUBSTITUTE($W$2, "Optimistic (", ""), "%)", "") / 100)) -> 12.5 | X7: =V7 + (W7 * (SUBSTITUTE(SUBSTITUTE($W$2, "Optimistic (", ""), "%)", "") / 100)) -> 31.25 | Y7: =(W7+(4*V7)+X7)/6 -> 23.958333 | Z7: =Y7/2 -> 11.979167 | AA7: 46150 | AB7: 46156 | AC7: 46157 | AD7: 46161 | AE7: =IF($Z7="",0,IF($M7="",0,$M7)) -> 0 | AF7: =IF(OR($Z7="",$N7=""),0,$Z7*5%) -> 0 | AG7: =IF(OR($Z7="",$O7=""),0,$Z7*10%) -> 0 | AH7: =IF($Z7="",0,IF(AND($P7="",$Q7=""),($Z7-$AE7-$AF7-$AG7-$AI7-$AK7-$AL7-$AM7-$AN7-$AO7),IF($P7="",0,IF($Q7="",($Z7-$AE7-$AF7-$AG7-$AI7-$AK7-$AL7-$AM7-$AN7-$AO7),($Z7-$AE7-$AF7-$AG7-$AI7-$AK7-$AL7-$AM7-$AN7-$AO7)*40%/(40%+15%))))) -> 2.8257576 | AI7: =IF($Z7="",0,IF($P7="",0,0.5)) -> 0.5 | AJ7: =IF($Z7="",0,IF(AND($P7="",$Q7=""),0,IF($Q7="",0,IF($P7="",($Z7-$AE7-$AF7-$AG7-$AI7-$AK7-$AL7-$AM7-$AN7-$AO7),($Z7-$AE7-$AF7-$AG7-$AI7-$AK7-$AL7-$AM7-$AN7-$AO7)*15%/(40%+15%))))) -> 1.0596591 | AK7: =IF($Z7="",0,$Z7*15%) -> 1.796875 | AL7: =IF($Z7="",0,IF($R7="",0,$R7)) -> 0 | AM7: =IF(OR($Z7="",$S7=""),0,$Z7*5%) -> 0.59895833 | AN7: =IF(OR($Z7="",$T7=""),0,$Z7*10%) -> 1.1979167 | AO7: =IF($Z7="",0,IF($U7="",0,$U7)) -> 4 | AP7: =SUM(AE7:AM7) -> 6.78125 | AQ7: Need to understand this
A8: 6 | D8: Support for Wide tables from API Source | E8: https://octopusdtlsupport.atlassian.net/browse/O2-2189 | F8: RnD | K8: 2 | P8: =10+2 -> 12 | Q8: 2 | S8: 2 | T8: 5 | U8: =(10+2)/3 -> 4 | V8: =SUM(M8:U8) -> 25 | W8: =V8 - (V8 * (SUBSTITUTE(SUBSTITUTE($W$2, "Optimistic (", ""), "%)", "") / 100)) -> 12.5 | X8: =V8 + (W8 * (SUBSTITUTE(SUBSTITUTE($W$2, "Optimistic (", ""), "%)", "") / 100)) -> 31.25 | Y8: =(W8+(4*V8)+X8)/6 -> 23.958333 | Z8: =Y8/2 -> 11.979167 | AA8: 46164 | AB8: 46170 | AC8: 46171 | AD8: 46175 | AE8: =IF($Z8="",0,IF($M8="",0,$M8)) -> 0 | AF8: =IF(OR($Z8="",$N8=""),0,$Z8*5%) -> 0 | AG8: =IF(OR($Z8="",$O8=""),0,$Z8*10%) -> 0 | AH8: =IF($Z8="",0,IF(AND($P8="",$Q8=""),($Z8-$AE8-$AF8-$AG8-$AI8-$AK8-$AL8-$AM8-$AN8-$AO8),IF($P8="",0,IF($Q8="",($Z8-$AE8-$AF8-$AG8-$AI8-$AK8-$AL8-$AM8-$AN8-$AO8),($Z8-$AE8-$AF8-$AG8-$AI8-$AK8-$AL8-$AM8-$AN8-$AO8)*40%/(40%+15%))))) -> 2.8257576 | AI8: =IF($Z8="",0,IF($P8="",0,0.5)) -> 0.5 | AJ8: =IF($Z8="",0,IF(AND($P8="",$Q8=""),0,IF($Q8="",0,IF($P8="",($Z8-$AE8-$AF8-$AG8-$AI8-$AK8-$AL8-$AM8-$AN8-$AO8),($Z8-$AE8-$AF8-$AG8-$AI8-$AK8-$AL8-$AM8-$AN8-$AO8)*15%/(40%+15%))))) -> 1.0596591 | AK8: =IF($Z8="",0,$Z8*15%) -> 1.796875 | AL8: =IF($Z8="",0,IF($R8="",0,$R8)) -> 0 | AM8: =IF(OR($Z8="",$S8=""),0,$Z8*5%) -> 0.59895833 | AN8: =IF(OR($Z8="",$T8=""),0,$Z8*10%) -> 1.1979167 | AO8: =IF($Z8="",0,IF($U8="",0,$U8)) -> 4 | AP8: =SUM(AE8:AM8) -> 6.78125 | AQ8: Need to understand this
A9: 7 | D9: Support for Wide tables from SFTP Source | E9: https://octopusdtlsupport.atlassian.net/browse/O2-2190 | F9: RnD | K9: 2 | M9: 0 | P9: =10+2 -> 12 | Q9: 2 | R9: 0 | S9: 2 | T9: 5 | U9: =(10+2)/3 -> 4 | V9: =SUM(M9:U9) -> 25 | W9: =V9 - (V9 * (SUBSTITUTE(SUBSTITUTE($W$2, "Optimistic (", ""), "%)", "") / 100)) -> 12.5 | X9: =V9 + (W9 * (SUBSTITUTE(SUBSTITUTE($W$2, "Optimistic (", ""), "%)", "") / 100)) -> 31.25 | Y9: =(W9+(4*V9)+X9)/6 -> 23.958333 | Z9: =Y9/2 -> 11.979167 | AA9: 46176 | AB9: 46182 | AC9: 46183 | AD9: 46185 | AE9: =IF($Z9="",0,IF($M9="",0,$M9)) -> 0 | AF9: =IF(OR($Z9="",$N9=""),0,$Z9*5%) -> 0 | AG9: =IF(OR($Z9="",$O9=""),0,$Z9*10%) -> 0 | AH9: =IF($Z9="",0,IF(AND($P9="",$Q9=""),($Z9-$AE9-$AF9-$AG9-$AI9-$AK9-$AL9-$AM9-$AN9-$AO9),IF($P9="",0,IF($Q9="",($Z9-$AE9-$AF9-$AG9-$AI9-$AK9-$AL9-$AM9-$AN9-$AO9),($Z9-$AE9-$AF9-$AG9-$AI9-$AK9-$AL9-$AM9-$AN9-$AO9)*40%/(40%+15%))))) -> 2.8257576 | AI9: =IF($Z9="",0,IF($P9="",0,0.5)) -> 0.5 | AJ9: =IF($Z9="",0,IF(AND($P9="",$Q9=""),0,IF($Q9="",0,IF($P9="",($Z9-$AE9-$AF9-$AG9-$AI9-$AK9-$AL9-$AM9-$AN9-$AO9),($Z9-$AE9-$AF9-$AG9-$AI9-$AK9-$AL9-$AM9-$AN9-$AO9)*15%/(40%+15%))))) -> 1.0596591 | AK9: =IF($Z9="",0,$Z9*15%) -> 1.796875 | AL9: =IF($Z9="",0,IF($R9="",0,$R9)) -> 0 | AM9: =IF(OR($Z9="",$S9=""),0,$Z9*5%) -> 0.59895833 | AN9: =IF(OR($Z9="",$T9=""),0,$Z9*10%) -> 1.1979167 | AO9: =IF($Z9="",0,IF($U9="",0,$U9)) -> 4 | AP9: =SUM(AE9:AM9) -> 6.78125 | AQ9: Need to understand this
D10: OmniEdge diagnostics metrics collection | E10: https://octopusdtlsupport.atlassian.net/browse/O2-2269 | F10: RnD | M10: 2 | N10: 2 | O10: 3 | P10: 2 | Q10: 1 | R10: 0 | S10: 0 | T10: 0 | U10: 3 | V10: 17 | W10: =V10 - (V10 * (SUBSTITUTE(SUBSTITUTE($W$2, "Optimistic (", ""), "%)", "") / 100)) -> 8.5 | X10: =V10 + (W10 * (SUBSTITUTE(SUBSTITUTE($W$2, "Optimistic (", ""), "%)", "") / 100)) -> 21.25 | Y10: =(W10+(4*V10)+X10)/6 -> 16.291667 | Z10: =Y10/2 -> 8.1458333 | AA10: =DATEVALUE("04/08/2026") -> 46120 | AB10: =DATEVALUE("04/17/2026") -> 46129 | AC10: 46136 | AD10: 46142 | AE10: =IF($Z10="",0,IF($M10="",0,$M10)) -> 2 | AF10: =IF(OR($Z10="",$N10=""),0,$Z10*5%) -> 0.40729167 | AG10: =IF(OR($Z10="",$O10=""),0,$Z10*10%) -> 0.81458333 | AH10: =IF($Z10="",0,IF(AND($P10="",$Q10=""),($Z10-$AE10-$AF10-$AG10-$AI10-$AK10-$AL10-$AM10-$AN10-$AO10),IF($P10="",0,IF($Q10="",($Z10-$AE10-$AF10-$AG10-$AI10-$AK10-$AL10-$AM10-$AN10-$AO10),($Z10-$AE10-$AF10-$AG10-$AI10-$AK10-$AL10-$AM10-$AN10-$AO10)*40%/(40%+15%))))) -> -0.74166667 | AI10: =IF($Z10="",0,IF($P10="",0,0.5)) -> 0.5 | AJ10: =IF($Z10="",0,IF(AND($P10="",$Q10=""),0,IF($Q10="",0,IF($P10="",($Z10-$AE10-$AF10-$AG10-$AI10-$AK10-$AL10-$AM10-$AN10-$AO10),($Z10-$AE10-$AF10-$AG10-$AI10-$AK10-$AL10-$AM10-$AN10-$AO10)*15%/(40%+15%))))) -> -0.278125 | AK10: =IF($Z10="",0,$Z10*15%) -> 1.221875 | AL10: =IF($Z10="",0,IF($R10="",0,$R10)) -> 0 | AM10: =IF(OR($Z10="",$S10=""),0,$Z10*5%) -> 0.40729167 | AN10: =IF(OR($Z10="",$T10=""),0,$Z10*10%) -> 0.81458333 | AO10: =IF($Z10="",0,IF($U10="",0,$U10)) -> 3 | AP10: =SUM(AE10:AM10) -> 4.33125
A11: 8 | B11: Enrichment | C11: APX | D11: APX - WhatIf Pump | F11: Process Team | H11: 1 | K11: 1 | L11: Plan | M11: 0 | Q11: 1 | R11: =4+4 -> 8 | T11: 1 | U11: 1 | V11: =SUM(M11:U11) -> 11 | W11: =V11 - (V11 * (SUBSTITUTE(SUBSTITUTE($W$2, "Optimistic (", ""), "%)", "") / 100)) -> 5.5 | X11: =V11 + (W11 * (SUBSTITUTE(SUBSTITUTE($W$2, "Optimistic (", ""), "%)", "") / 100)) -> 13.75 | Y11: =(W11+(4*V11)+X11)/6 -> 10.541667 | Z11: =Y11/2 -> 5.2708333 | AE11: =IF($Z11="",0,IF($M11="",0,$M11)) -> 0 | AF11: =IF(OR($Z11="",$N11=""),0,$Z11*5%) -> 0 | AG11: =IF(OR($Z11="",$O11=""),0,$Z11*10%) -> 0 | AH11: =IF($Z11="",0,IF(AND($P11="",$Q11=""),($Z11-$AE11-$AF11-$AG11-$AI11-$AK11-$AL11-$AM11-$AN11-$AO11),IF($P11="",0,IF($Q11="",($Z11-$AE11-$AF11-$AG11-$AI11-$AK11-$AL11-$AM11-$AN11-$AO11),($Z11-$AE11-$AF11-$AG11-$AI11-$AK11-$AL11-$AM11-$AN11-$AO11)*40%/(40%+15%))))) -> 0 | AI11: =IF($Z11="",0,IF($P11="",0,0.5)) -> 0 | AJ11: =IF($Z11="",0,IF(AND($P11="",$Q11=""),0,IF($Q11="",0,IF($P11="",($Z11-$AE11-$AF11-$AG11-$AI11-$AK11-$AL11-$AM11-$AN11-$AO11),($Z11-$AE11-$AF11-$AG11-$AI11-$AK11-$AL11-$AM11-$AN11-$AO11)*15%/(40%+15%))))) -> -5.046875 | AK11: =IF($Z11="",0,$Z11*15%) -> 0.790625 | AL11: =IF($Z11="",0,IF($R11="",0,$R11)) -> 8 | AM11: =IF(OR($Z11="",$S11=""),0,$Z11*5%) -> 0 | AN11: =IF(OR($Z11="",$T11=""),0,$Z11*10%) -> 0.52708333 | AO11: =IF($Z11="",0,IF($U11="",0,$U11)) -> 1 | AP11: =SUM(AE11:AM11) -> 3.74375
A12: 9 | D12: APX - WhatIf Compressor | F12: Process Team | H12: 1 | K12: 1 | L12: Plan | M12: 0 | Q12: 1 | R12: 3 | T12: 1 | U12: 1 | V12: =SUM(M12:U12) -> 6 | W12: =V12 - (V12 * (SUBSTITUTE(SUBSTITUTE($W$2, "Optimistic (", ""), "%)", "") / 100)) -> 3 | X12: =V12 + (W12 * (SUBSTITUTE(SUBSTITUTE($W$2, "Optimistic (", ""), "%)", "") / 100)) -> 7.5 | Y12: =(W12+(4*V12)+X12)/6 -> 5.75 | Z12: =Y12/2 -> 2.875 | AE12: =IF($Z12="",0,IF($M12="",0,$M12)) -> 0 | AF12: =IF(OR($Z12="",$N12=""),0,$Z12*5%) -> 0 | AG12: =IF(OR($Z12="",$O12=""),0,$Z12*10%) -> 0 | AH12: =IF($Z12="",0,IF(AND($P12="",$Q12=""),($Z12-$AE12-$AF12-$AG12-$AI12-$AK12-$AL12-$AM12-$AN12-$AO12),IF($P12="",0,IF($Q12="",($Z12-$AE12-$AF12-$AG12-$AI12-$AK12-$AL12-$AM12-$AN12-$AO12),($Z12-$AE12-$AF12-$AG12-$AI12-$AK12-$AL12-$AM12-$AN12-$AO12)*40%/(40%+15%))))) -> 0 | AI12: =IF($Z12="",0,IF($P12="",0,0.5)) -> 0 | AJ12: =IF($Z12="",0,IF(AND($P12="",$Q12=""),0,IF($Q12="",0,IF($P12="",($Z12-$AE12-$AF12-$AG12-$AI12-$AK12-$AL12-$AM12-$AN12-$AO12),($Z12-$AE12-$AF12-$AG12-$AI12-$AK12-$AL12-$AM12-$AN12-$AO12)*15%/(40%+15%))))) -> -1.84375 | AK12: =IF($Z12="",0,$Z12*15%) -> 0.43125 | AL12: =IF($Z12="",0,IF($R12="",0,$R12)) -> 3 | AM12: =IF(OR($Z12="",$S12=""),0,$Z12*5%) -> 0 | AN12: =IF(OR($Z12="",$T12=""),0,$Z12*10%) -> 0.2875 | AO12: =IF($Z12="",0,IF($U12="",0,$U12)) -> 1 | AP12: =SUM(AE12:AM12) -> 1.5875
A13: 10 | D13: APX - WhatIf Condenser | F13: Process Team | H13: 1 | K13: 1 | L13: Plan | M13: 0 | Q13: 1 | R13: 5 | T13: 1 | U13: 1 | V13: =SUM(M13:U13) -> 8 | W13: =V13 - (V13 * (SUBSTITUTE(SUBSTITUTE($W$2, "Optimistic (", ""), "%)", "") / 100)) -> 4 | X13: =V13 + (W13 * (SUBSTITUTE(SUBSTITUTE($W$2, "Optimistic (", ""), "%)", "") / 100)) -> 10 | Y13: =(W13+(4*V13)+X13)/6 -> 7.6666667 | Z13: =Y13/2 -> 3.8333333 | AE13: =IF($Z13="",0,IF($M13="",0,$M13)) -> 0 | AF13: =IF(OR($Z13="",$N13=""),0,$Z13*5%) -> 0 | AG13: =IF(OR($Z13="",$O13=""),0,$Z13*10%) -> 0 | AH13: =IF($Z13="",0,IF(AND($P13="",$Q13=""),($Z13-$AE13-$AF13-$AG13-$AI13-$AK13-$AL13-$AM13-$AN13-$AO13),IF($P13="",0,IF($Q13="",($Z13-$AE13-$AF13-$AG13-$AI13-$AK13-$AL13-$AM13-$AN13-$AO13),($Z13-$AE13-$AF13-$AG13-$AI13-$AK13-$AL13-$AM13-$AN13-$AO13)*40%/(40%+15%))))) -> 0 | AI13: =IF($Z13="",0,IF($P13="",0,0.5)) -> 0 | AJ13: =IF($Z13="",0,IF(AND($P13="",$Q13=""),0,IF($Q13="",0,IF($P13="",($Z13-$AE13-$AF13-$AG13-$AI13-$AK13-$AL13-$AM13-$AN13-$AO13),($Z13-$AE13-$AF13-$AG13-$AI13-$AK13-$AL13-$AM13-$AN13-$AO13)*15%/(40%+15%))))) -> -3.125 | AK13: =IF($Z13="",0,$Z13*15%) -> 0.575 | AL13: =IF($Z13="",0,IF($R13="",0,$R13)) -> 5 | AM13: =IF(OR($Z13="",$S13=""),0,$Z13*5%) -> 0 | AN13: =IF(OR($Z13="",$T13=""),0,$Z13*10%) -> 0.38333333 | AO13: =IF($Z13="",0,IF($U13="",0,$U13)) -> 1 | AP13: =SUM(AE13:AM13) -> 2.45
A14: 11 | D14: APX - WhatIf Heat Exchanger | F14: Process Team | H14: 1 | K14: 1 | L14: Plan | M14: 0 | Q14: 1 | R14: 3 | T14: 1 | U14: 1 | V14: =SUM(M14:U14) -> 6 | W14: =V14 - (V14 * (SUBSTITUTE(SUBSTITUTE($W$2, "Optimistic (", ""), "%)", "") / 100)) -> 3 | X14: =V14 + (W14 * (SUBSTITUTE(SUBSTITUTE($W$2, "Optimistic (", ""), "%)", "") / 100)) -> 7.5 | Y14: =(W14+(4*V14)+X14)/6 -> 5.75 | Z14: =Y14/2 -> 2.875 | AE14: =IF($Z14="",0,IF($M14="",0,$M14)) -> 0 | AF14: =IF(OR($Z14="",$N14=""),0,$Z14*5%) -> 0 | AG14: =IF(OR($Z14="",$O14=""),0,$Z14*10%) -> 0 | AH14: =IF($Z14="",0,IF(AND($P14="",$Q14=""),($Z14-$AE14-$AF14-$AG14-$AI14-$AK14-$AL14-$AM14-$AN14-$AO14),IF($P14="",0,IF($Q14="",($Z14-$AE14-$AF14-$AG14-$AI14-$AK14-$AL14-$AM14-$AN14-$AO14),($Z14-$AE14-$AF14-$AG14-$AI14-$AK14-$AL14-$AM14-$AN14-$AO14)*40%/(40%+15%))))) -> 0 | AI14: =IF($Z14="",0,IF($P14="",0,0.5)) -> 0 | AJ14: =IF($Z14="",0,IF(AND($P14="",$Q14=""),0,IF($Q14="",0,IF($P14="",($Z14-$AE14-$AF14-$AG14-$AI14-$AK14-$AL14-$AM14-$AN14-$AO14),($Z14-$AE14-$AF14-$AG14-$AI14-$AK14-$AL14-$AM14-$AN14-$AO14)*15%/(40%+15%))))) -> -1.84375 | AK14: =IF($Z14="",0,$Z14*15%) -> 0.43125 | AL14: =IF($Z14="",0,IF($R14="",0,$R14)) -> 3 | AM14: =IF(OR($Z14="",$S14=""),0,$Z14*5%) -> 0 | AN14: =IF(OR($Z14="",$T14=""),0,$Z14*10%) -> 0.2875 | AO14: =IF($Z14="",0,IF($U14="",0,$U14)) -> 1 | AP14: =SUM(AE14:AM14) -> 1.5875
A15: 12 | D15: APX - WhatIf Boiler | F15: Process Team | H15: 1 | K15: 1 | L15: Plan | M15: 0 | Q15: 1 | R15: 0 | T15: 1 | U15: 1 | V15: =SUM(M15:U15) -> 3 | W15: =V15 - (V15 * (SUBSTITUTE(SUBSTITUTE($W$2, "Optimistic (", ""), "%)", "") / 100)) -> 1.5 | X15: =V15 + (W15 * (SUBSTITUTE(SUBSTITUTE($W$2, "Optimistic (", ""), "%)", "") / 100)) -> 3.75 | Y15: =(W15+(4*V15)+X15)/6 -> 2.875 | Z15: =Y15/2 -> 1.4375 | AE15: =IF($Z15="",0,IF($M15="",0,$M15)) -> 0 | AF15: =IF(OR($Z15="",$N15=""),0,$Z15*5%) -> 0 | AG15: =IF(OR($Z15="",$O15=""),0,$Z15*10%) -> 0 | AH15: =IF($Z15="",0,IF(AND($P15="",$Q15=""),($Z15-$AE15-$AF15-$AG15-$AI15-$AK15-$AL15-$AM15-$AN15-$AO15),IF($P15="",0,IF($Q15="",($Z15-$AE15-$AF15-$AG15-$AI15-$AK15-$AL15-$AM15-$AN15-$AO15),($Z15-$AE15-$AF15-$AG15-$AI15-$AK15-$AL15-$AM15-$AN15-$AO15)*40%/(40%+15%))))) -> 0 | AI15: =IF($Z15="",0,IF($P15="",0,0.5)) -> 0 | AJ15: =IF($Z15="",0,IF(AND($P15="",$Q15=""),0,IF($Q15="",0,IF($P15="",($Z15-$AE15-$AF15-$AG15-$AI15-$AK15-$AL15-$AM15-$AN15-$AO15),($Z15-$AE15-$AF15-$AG15-$AI15-$AK15-$AL15-$AM15-$AN15-$AO15)*15%/(40%+15%))))) -> 0.078125 | AK15: =IF($Z15="",0,$Z15*15%) -> 0.215625 | AL15: =IF($Z15="",0,IF($R15="",0,$R15)) -> 0 | AM15: =IF(OR($Z15="",$S15=""),0,$Z15*5%) -> 0 | AN15: =IF(OR($Z15="",$T15=""),0,$Z15*10%) -> 0.14375 | AO15: =IF($Z15="",0,IF($U15="",0,$U15)) -> 1 | AP15: =SUM(AE15:AM15) -> 0.29375
A16: 13 | D16: APX - Health Pump | F16: Process Team | H16: 1 | K16: 1 | L16: Plan | M16: 0 | Q16: 1 | R16: 4 | T16: 1 | U16: 1 | V16: =SUM(M16:U16) -> 7 | W16: =V16 - (V16 * (SUBSTITUTE(SUBSTITUTE($W$2, "Optimistic (", ""), "%)", "") / 100)) -> 3.5 | X16: =V16 + (W16 * (SUBSTITUTE(SUBSTITUTE($W$2, "Optimistic (", ""), "%)", "") / 100)) -> 8.75 | Y16: =(W16+(4*V16)+X16)/6 -> 6.7083333 | Z16: =Y16/2 -> 3.3541667 | AE16: =IF($Z16="",0,IF($M16="",0,$M16)) -> 0 | AF16: =IF(OR($Z16="",$N16=""),0,$Z16*5%) -> 0 | AG16: =IF(OR($Z16="",$O16=""),0,$Z16*10%) -> 0 | AH16: =IF($Z16="",0,IF(AND($P16="",$Q16=""),($Z16-$AE16-$AF16-$AG16-$AI16-$AK16-$AL16-$AM16-$AN16-$AO16),IF($P16="",0,IF($Q16="",($Z16-$AE16-$AF16-$AG16-$AI16-$AK16-$AL16-$AM16-$AN16-$AO16),($Z16-$AE16-$AF16-$AG16-$AI16-$AK16-$AL16-$AM16-$AN16-$AO16)*40%/(40%+15%))))) -> 0 | AI16: =IF($Z16="",0,IF($P16="",0,0.5)) -> 0 | AJ16: =IF($Z16="",0,IF(AND($P16="",$Q16=""),0,IF($Q16="",0,IF($P16="",($Z16-$AE16-$AF16-$AG16-$AI16-$AK16-$AL16-$AM16-$AN16-$AO16),($Z16-$AE16-$AF16-$AG16-$AI16-$AK16-$AL16-$AM16-$AN16-$AO16)*15%/(40%+15%))))) -> -2.484375 | AK16: =IF($Z16="",0,$Z16*15%) -> 0.503125 | AL16: =IF($Z16="",0,IF($R16="",0,$R16)) -> 4 | AM16: =IF(OR($Z16="",$S16=""),0,$Z16*5%) -> 0 | AN16: =IF(OR($Z16="",$T16=""),0,$Z16*10%) -> 0.33541667 | AO16: =IF($Z16="",0,IF($U16="",0,$U16)) -> 1 | AP16: =SUM(AE16:AM16) -> 2.01875
A17: 14 | D17: APX - Health Compressor | F17: Process Team | H17: 1 | K17: 1 | L17: Plan | M17: 0 | Q17: 1 | R17: 3 | T17: 1 | U17: 1 | V17: =SUM(M17:U17) -> 6 | W17: =V17 - (V17 * (SUBSTITUTE(SUBSTITUTE($W$2, "Optimistic (", ""), "%)", "") / 100)) -> 3 | X17: =V17 + (W17 * (SUBSTITUTE(SUBSTITUTE($W$2, "Optimistic (", ""), "%)", "") / 100)) -> 7.5 | Y17: =(W17+(4*V17)+X17)/6 -> 5.75 | Z17: =Y17/2 -> 2.875 | AE17: =IF($Z17="",0,IF($M17="",0,$M17)) -> 0 | AF17: =IF(OR($Z17="",$N17=""),0,$Z17*5%) -> 0 | AG17: =IF(OR($Z17="",$O17=""),0,$Z17*10%) -> 0 | AH17: =IF($Z17="",0,IF(AND($P17="",$Q17=""),($Z17-$AE17-$AF17-$AG17-$AI17-$AK17-$AL17-$AM17-$AN17-$AO17),IF($P17="",0,IF($Q17="",($Z17-$AE17-$AF17-$AG17-$AI17-$AK17-$AL17-$AM17-$AN17-$AO17),($Z17-$AE17-$AF17-$AG17-$AI17-$AK17-$AL17-$AM17-$AN17-$AO17)*40%/(40%+15%))))) -> 0 | AI17: =IF($Z17="",0,IF($P17="",0,0.5)) -> 0 | AJ17: =IF($Z17="",0,IF(AND($P17="",$Q17=""),0,IF($Q17="",0,IF($P17="",($Z17-$AE17-$AF17-$AG17-$AI17-$AK17-$AL17-$AM17-$AN17-$AO17),($Z17-$AE17-$AF17-$AG17-$AI17-$AK17-$AL17-$AM17-$AN17-$AO17)*15%/(40%+15%))))) -> -1.84375 | AK17: =IF($Z17="",0,$Z17*15%) -> 0.43125 | AL17: =IF($Z17="",0,IF($R17="",0,$R17)) -> 3 | AM17: =IF(OR($Z17="",$S17=""),0,$Z17*5%) -> 0 | AN17: =IF(OR($Z17="",$T17=""),0,$Z17*10%) -> 0.2875 | AO17: =IF($Z17="",0,IF($U17="",0,$U17)) -> 1 | AP17: =SUM(AE17:AM17) -> 1.5875
A18: 15 | D18: APX - Health Motor | F18: Process Team | H18: 1 | K18: 1 | L18: Plan | M18: 0 | Q18: 1 | R18: 4 | T18: 1 | U18: 1 | V18: =SUM(M18:U18) -> 7 | W18: =V18 - (V18 * (SUBSTITUTE(SUBSTITUTE($W$2, "Optimistic (", ""), "%)", "") / 100)) -> 3.5 | X18: =V18 + (W18 * (SUBSTITUTE(SUBSTITUTE($W$2, "Optimistic (", ""), "%)", "") / 100)) -> 8.75 | Y18: =(W18+(4*V18)+X18)/6 -> 6.7083333 | Z18: =Y18/2 -> 3.3541667 | AE18: =IF($Z18="",0,IF($M18="",0,$M18)) -> 0 | AF18: =IF(OR($Z18="",$N18=""),0,$Z18*5%) -> 0 | AG18: =IF(OR($Z18="",$O18=""),0,$Z18*10%) -> 0 | AH18: =IF($Z18="",0,IF(AND($P18="",$Q18=""),($Z18-$AE18-$AF18-$AG18-$AI18-$AK18-$AL18-$AM18-$AN18-$AO18),IF($P18="",0,IF($Q18="",($Z18-$AE18-$AF18-$AG18-$AI18-$AK18-$AL18-$AM18-$AN18-$AO18),($Z18-$AE18-$AF18-$AG18-$AI18-$AK18-$AL18-$AM18-$AN18-$AO18)*40%/(40%+15%))))) -> 0 | AI18: =IF($Z18="",0,IF($P18="",0,0.5)) -> 0 | AJ18: =IF($Z18="",0,IF(AND($P18="",$Q18=""),0,IF($Q18="",0,IF($P18="",($Z18-$AE18-$AF18-$AG18-$AI18-$AK18-$AL18-$AM18-$AN18-$AO18),($Z18-$AE18-$AF18-$AG18-$AI18-$AK18-$AL18-$AM18-$AN18-$AO18)*15%/(40%+15%))))) -> -2.484375 | AK18: =IF($Z18="",0,$Z18*15%) -> 0.503125 | AL18: =IF($Z18="",0,IF($R18="",0,$R18)) -> 4 | AM18: =IF(OR($Z18="",$S18=""),0,$Z18*5%) -> 0 | AN18: =IF(OR($Z18="",$T18=""),0,$Z18*10%) -> 0.33541667 | AO18: =IF($Z18="",0,IF($U18="",0,$U18)) -> 1 | AP18: =SUM(AE18:AM18) -> 2.01875
A19: 16 | D19: DEV - WhatIf Visual Screens (Pump, Comp,Cond,Hex, Boiler) II | E19: https://octopusdtlsupport.atlassian.net/browse/O2-1991 | F19: Process Team | H19: 1 | K19: 1 | L19: UnPlan | M19: 1 | O19: 5 | P19: 30 | Q19: 5 | R19: 3 | U19: 3 | V19: =SUM(M19:U19) -> 47 | W19: =V19 - (V19 * (SUBSTITUTE(SUBSTITUTE($W$2, "Optimistic (", ""), "%)", "") / 100)) -> 23.5 | X19: =V19 + (W19 * (SUBSTITUTE(SUBSTITUTE($W$2, "Optimistic (", ""), "%)", "") / 100)) -> 58.75 | Y19: =(W19+(4*V19)+X19)/6 -> 45.041667 | Z19: =Y19/2 -> 22.520833 | AA19: 46118 | AB19: 46135 | AC19: 46136 | AD19: 46141 | AE19: =IF($Z19="",0,IF($M19="",0,$M19)) -> 1 | AF19: =IF(OR($Z19="",$N19=""),0,$Z19*5%) -> 0 | AG19: =IF(OR($Z19="",$O19=""),0,$Z19*10%) -> 2.2520833 | AH19: =IF($Z19="",0,IF(AND($P19="",$Q19=""),($Z19-$AE19-$AF19-$AG19-$AI19-$AK19-$AL19-$AM19-$AN19-$AO19),IF($P19="",0,IF($Q19="",($Z19-$AE19-$AF19-$AG19-$AI19-$AK19-$AL19-$AM19-$AN19-$AO19),($Z19-$AE19-$AF19-$AG19-$AI19-$AK19-$AL19-$AM19-$AN19-$AO19)*40%/(40%+15%))))) -> 6.8295455 | AI19: =IF($Z19="",0,IF($P19="",0,0.5)) -> 0.5 | AJ19: =IF($Z19="",0,IF(AND($P19="",$Q19=""),0,IF($Q19="",0,IF($P19="",($Z19-$AE19-$AF19-$AG19-$AI19-$AK19-$AL19-$AM19-$AN19-$AO19),($Z19-$AE19-$AF19-$AG19-$AI19-$AK19-$AL19-$AM19-$AN19-$AO19)*15%/(40%+15%))))) -> 2.5610795 | AK19: =IF($Z19="",0,$Z19*15%) -> 3.378125 | AL19: =IF($Z19="",0,IF($R19="",0,$R19)) -> 3 | AM19: =IF(OR($Z19="",$S19=""),0,$Z19*5%) -> 0 | AN19: =IF(OR($Z19="",$T19=""),0,$Z19*10%) -> 0 | AO19: =IF($Z19="",0,IF($U19="",0,$U19)) -> 3 | AP19: =SUM(AE19:AM19) -> 19.520833
A20: 17 | D20: DEV - Tempate Tool Enhancement for WhatIf and Health | E20: https://octopusdtlsupport.atlassian.net/browse/O2-2186 | F20: Process Team | H20: 1 | K20: 1 | M20: 4 | P20: 20 | Q20: 10 | R20: 5 | S20: 5 | U20: 3 | V20: =SUM(M20:U20) -> 47 | W20: =V20 - (V20 * (SUBSTITUTE(SUBSTITUTE($W$2, "Optimistic (", ""), "%)", "") / 100)) -> 23.5 | X20: =V20 + (W20 * (SUBSTITUTE(SUBSTITUTE($W$2, "Optimistic (", ""), "%)", "") / 100)) -> 58.75 | Y20: =(W20+(4*V20)+X20)/6 -> 45.041667 | Z20: =Y20/2 -> 22.520833 | AA20: 46118 | AB20: 46128 | AC20: 46129 | AD20: 46139 | AE20: =IF($Z20="",0,IF($M20="",0,$M20)) -> 4 | AF20: =IF(OR($Z20="",$N20=""),0,$Z20*5%) -> 0 | AG20: =IF(OR($Z20="",$O20=""),0,$Z20*10%) -> 0 | AH20: =IF($Z20="",0,IF(AND($P20="",$Q20=""),($Z20-$AE20-$AF20-$AG20-$AI20-$AK20-$AL20-$AM20-$AN20-$AO20),IF($P20="",0,IF($Q20="",($Z20-$AE20-$AF20-$AG20-$AI20-$AK20-$AL20-$AM20-$AN20-$AO20),($Z20-$AE20-$AF20-$AG20-$AI20-$AK20-$AL20-$AM20-$AN20-$AO20)*40%/(40%+15%))))) -> 4.0121212 | AI20: =IF($Z20="",0,IF($P20="",0,0.5)) -> 0.5 | AJ20: =IF($Z20="",0,IF(AND($P20="",$Q20=""),0,IF($Q20="",0,IF($P20="",($Z20-$AE20-$AF20-$AG20-$AI20-$AK20-$AL20-$AM20-$AN20-$AO20),($Z20-$AE20-$AF20-$AG20-$AI20-$AK20-$AL20-$AM20-$AN20-$AO20)*15%/(40%+15%))))) -> 1.5045455 | AK20: =IF($Z20="",0,$Z20*15%) -> 3.378125 | AL20: =IF($Z20="",0,IF($R20="",0,$R20)) -> 5 | AM20: =IF(OR($Z20="",$S20=""),0,$Z20*5%) -> 1.1260417 | AN20: =IF(OR($Z20="",$T20=""),0,$Z20*10%) -> 0 | AO20: =IF($Z20="",0,IF($U20="",0,$U20)) -> 3 | AP20: =SUM(AE20:AM20) -> 19.520833
A21: 18 | D21: DEV - Performance Module Enhancements (Results in OC ) | F21: Process Team | H21: 1 | K21: 1 | L21: UnPlan | M21: 5 | R21: 0 | V21: =SUM(M21:U21) -> 5 | W21: =V21 - (V21 * (SUBSTITUTE(SUBSTITUTE($W$2, "Optimistic (", ""), "%)", "") / 100)) -> 2.5 | X21: =V21 + (W21 * (SUBSTITUTE(SUBSTITUTE($W$2, "Optimistic (", ""), "%)", "") / 100)) -> 6.25 | Y21: =(W21+(4*V21)+X21)/6 -> 4.7916667 | Z21: =Y21/2 -> 2.3958333 | AE21: =IF($Z21="",0,IF($M21="",0,$M21)) -> 5 | AF21: =IF(OR($Z21="",$N21=""),0,$Z21*5%) -> 0 | AG21: =IF(OR($Z21="",$O21=""),0,$Z21*10%) -> 0 | AH21: =IF($Z21="",0,IF(AND($P21="",$Q21=""),($Z21-$AE21-$AF21-$AG21-$AI21-$AK21-$AL21-$AM21-$AN21-$AO21),IF($P21="",0,IF($Q21="",($Z21-$AE21-$AF21-$AG21-$AI21-$AK21-$AL21-$AM21-$AN21-$AO21),($Z21-$AE21-$AF21-$AG21-$AI21-$AK21-$AL21-$AM21-$AN21-$AO21)*40%/(40%+15%))))) -> -2.9635417 | AI21: =IF($Z21="",0,IF($P21="",0,0.5)) -> 0 | AJ21: =IF($Z21="",0,IF(AND($P21="",$Q21=""),0,IF($Q21="",0,IF($P21="",($Z21-$AE21-$AF21-$AG21-$AI21-$AK21-$AL21-$AM21-$AN21-$AO21),($Z21-$AE21-$AF21-$AG21-$AI21-$AK21-$AL21-$AM21-$AN21-$AO21)*15%/(40%+15%))))) -> 0 | AK21: =IF($Z21="",0,$Z21*15%) -> 0.359375 | AL21: =IF($Z21="",0,IF($R21="",0,$R21)) -> 0 | AM21: =IF(OR($Z21="",$S21=""),0,$Z21*5%) -> 0 | AN21: =IF(OR($Z21="",$T21=""),0,$Z21*10%) -> 0 | AO21: =IF($Z21="",0,IF($U21="",0,$U21)) -> 0 | AP21: =SUM(AE21:AM21) -> 2.3958333
A22: 19 | D22: APX - Demos | F22: Process Team | H22: 1 | K22: 1+ | L22: Plan | M22: 8 | R22: 0 | V22: =SUM(M22:U22) -> 8 | W22: =V22 - (V22 * (SUBSTITUTE(SUBSTITUTE($W$2, "Optimistic (", ""), "%)", "") / 100)) -> 4 | X22: =V22 + (W22 * (SUBSTITUTE(SUBSTITUTE($W$2, "Optimistic (", ""), "%)", "") / 100)) -> 10 | Y22: =(W22+(4*V22)+X22)/6 -> 7.6666667 | Z22: =Y22/2 -> 3.8333333 | AE22: =IF($Z22="",0,IF($M22="",0,$M22)) -> 8 | AF22: =IF(OR($Z22="",$N22=""),0,$Z22*5%) -> 0 | AG22: =IF(OR($Z22="",$O22=""),0,$Z22*10%) -> 0 | AH22: =IF($Z22="",0,IF(AND($P22="",$Q22=""),($Z22-$AE22-$AF22-$AG22-$AI22-$AK22-$AL22-$AM22-$AN22-$AO22),IF($P22="",0,IF($Q22="",($Z22-$AE22-$AF22-$AG22-$AI22-$AK22-$AL22-$AM22-$AN22-$AO22),($Z22-$AE22-$AF22-$AG22-$AI22-$AK22-$AL22-$AM22-$AN22-$AO22)*40%/(40%+15%))))) -> -4.7416667 | AI22: =IF($Z22="",0,IF($P22="",0,0.5)) -> 0 | AJ22: =IF($Z22="",0,IF(AND($P22="",$Q22=""),0,IF($Q22="",0,IF($P22="",($Z22-$AE22-$AF22-$AG22-$AI22-$AK22-$AL22-$AM22-$AN22-$AO22),($Z22-$AE22-$AF22-$AG22-$AI22-$AK22-$AL22-$AM22-$AN22-$AO22)*15%/(40%+15%))))) -> 0 | AK22: =IF($Z22="",0,$Z22*15%) -> 0.575 | AL22: =IF($Z22="",0,IF($R22="",0,$R22)) -> 0 | AM22: =IF(OR($Z22="",$S22=""),0,$Z22*5%) -> 0 | AN22: =IF(OR($Z22="",$T22=""),0,$Z22*10%) -> 0 | AO22: =IF($Z22="",0,IF($U22="",0,$U22)) -> 0 | AP22: =SUM(AE22:AM22) -> 3.8333333
A23: 20 | C23: Batch / BPM | D23: IT/OT Conversion Batch/BPM (on hold) | F23: RnD | L23: UnPlan | M23: - | R23: - | V23: =SUM(M23:U23) -> 0 | W23: =V23 - (V23 * (SUBSTITUTE(SUBSTITUTE($W$2, "Optimistic (", ""), "%)", "") / 100)) -> 0 | X23: =V23 + (W23 * (SUBSTITUTE(SUBSTITUTE($W$2, "Optimistic (", ""), "%)", "") / 100)) -> 0 | Y23: =(W23+(4*V23)+X23)/6 -> 0 | Z23: =Y23/2 -> 0 | AE23: =IF($Z23="",0,IF($M23="",0,$M23)) -> - | AF23: =IF(OR($Z23="",$N23=""),0,$Z23*5%) -> 0 | AG23: =IF(OR($Z23="",$O23=""),0,$Z23*10%) -> 0 | AH23: =IF($Z23="",0,IF(AND($P23="",$Q23=""),($Z23-$AE23-$AF23-$AG23-$AI23-$AK23-$AL23-$AM23-$AN23-$AO23),IF($P23="",0,IF($Q23="",($Z23-$AE23-$AF23-$AG23-$AI23-$AK23-$AL23-$AM23-$AN23-$AO23),($Z23-$AE23-$AF23-$AG23-$AI23-$AK23-$AL23-$AM23-$AN23-$AO23)*40%/(40%+15%))))) -> #VALUE! | AI23: =IF($Z23="",0,IF($P23="",0,0.5)) -> 0 | AJ23: =IF($Z23="",0,IF(AND($P23="",$Q23=""),0,IF($Q23="",0,IF($P23="",($Z23-$AE23-$AF23-$AG23-$AI23-$AK23-$AL23-$AM23-$AN23-$AO23),($Z23-$AE23-$AF23-$AG23-$AI23-$AK23-$AL23-$AM23-$AN23-$AO23)*15%/(40%+15%))))) -> 0 | AK23: =IF($Z23="",0,$Z23*15%) -> 0 | AL23: =IF($Z23="",0,IF($R23="",0,$R23)) -> - | AM23: =IF(OR($Z23="",$S23=""),0,$Z23*5%) -> 0 | AN23: =IF(OR($Z23="",$T23=""),0,$Z23*10%) -> 0 | AO23: =IF($Z23="",0,IF($U23="",0,$U23)) -> 0 | AP23: =SUM(AE23:AM23) -> #VALUE!
A24: 21 | D24: Support for SQL Language in Batch/BPM(Features Supported by adx) (Discussion Required) | F24: RnD | K24: 2 | L24: UnPlan | M24: - | R24: - | V24: =SUM(M24:U24) -> 0 | W24: =V24 - (V24 * (SUBSTITUTE(SUBSTITUTE($W$2, "Optimistic (", ""), "%)", "") / 100)) -> 0 | X24: =V24 + (W24 * (SUBSTITUTE(SUBSTITUTE($W$2, "Optimistic (", ""), "%)", "") / 100)) -> 0 | Y24: =(W24+(4*V24)+X24)/6 -> 0 | Z24: =Y24/2 -> 0 | AE24: =IF($Z24="",0,IF($M24="",0,$M24)) -> - | AF24: =IF(OR($Z24="",$N24=""),0,$Z24*5%) -> 0 | AG24: =IF(OR($Z24="",$O24=""),0,$Z24*10%) -> 0 | AH24: =IF($Z24="",0,IF(AND($P24="",$Q24=""),($Z24-$AE24-$AF24-$AG24-$AI24-$AK24-$AL24-$AM24-$AN24-$AO24),IF($P24="",0,IF($Q24="",($Z24-$AE24-$AF24-$AG24-$AI24-$AK24-$AL24-$AM24-$AN24-$AO24),($Z24-$AE24-$AF24-$AG24-$AI24-$AK24-$AL24-$AM24-$AN24-$AO24)*40%/(40%+15%))))) -> #VALUE! | AI24: =IF($Z24="",0,IF($P24="",0,0.5)) -> 0 | AJ24: =IF($Z24="",0,IF(AND($P24="",$Q24=""),0,IF($Q24="",0,IF($P24="",($Z24-$AE24-$AF24-$AG24-$AI24-$AK24-$AL24-$AM24-$AN24-$AO24),($Z24-$AE24-$AF24-$AG24-$AI24-$AK24-$AL24-$AM24-$AN24-$AO24)*15%/(40%+15%))))) -> 0 | AK24: =IF($Z24="",0,$Z24*15%) -> 0 | AL24: =IF($Z24="",0,IF($R24="",0,$R24)) -> - | AM24: =IF(OR($Z24="",$S24=""),0,$Z24*5%) -> 0 | AN24: =IF(OR($Z24="",$T24=""),0,$Z24*10%) -> 0 | AO24: =IF($Z24="",0,IF($U24="",0,$U24)) -> 0 | AP24: =SUM(AE24:AM24) -> #VALUE!
A25: 25 | D25: "Create Asset from Template" Add BPM support (Discussion Required) | F25: RnD | G25: Faster Impl | K25: 2 | L25: UnPlan | V25: =SUM(M25:U25) -> 0 | W25: =V25 - (V25 * (SUBSTITUTE(SUBSTITUTE($W$2, "Optimistic (", ""), "%)", "") / 100)) -> 0 | X25: =V25 + (W25 * (SUBSTITUTE(SUBSTITUTE($W$2, "Optimistic (", ""), "%)", "") / 100)) -> 0 | Y25: =(W25+(4*V25)+X25)/6 -> 0 | Z25: =Y25/2 -> 0 | AE25: =IF($Z25="",0,IF($M25="",0,$M25)) -> 0 | AF25: =IF(OR($Z25="",$N25=""),0,$Z25*5%) -> 0 | AG25: =IF(OR($Z25="",$O25=""),0,$Z25*10%) -> 0 | AH25: =IF($Z25="",0,IF(AND($P25="",$Q25=""),($Z25-$AE25-$AF25-$AG25-$AI25-$AK25-$AL25-$AM25-$AN25-$AO25),IF($P25="",0,IF($Q25="",($Z25-$AE25-$AF25-$AG25-$AI25-$AK25-$AL25-$AM25-$AN25-$AO25),($Z25-$AE25-$AF25-$AG25-$AI25-$AK25-$AL25-$AM25-$AN25-$AO25)*40%/(40%+15%))))) -> 0 | AI25: =IF($Z25="",0,IF($P25="",0,0.5)) -> 0 | AJ25: =IF($Z25="",0,IF(AND($P25="",$Q25=""),0,IF($Q25="",0,IF($P25="",($Z25-$AE25-$AF25-$AG25-$AI25-$AK25-$AL25-$AM25-$AN25-$AO25),($Z25-$AE25-$AF25-$AG25-$AI25-$AK25-$AL25-$AM25-$AN25-$AO25)*15%/(40%+15%))))) -> 0 | AK25: =IF($Z25="",0,$Z25*15%) -> 0 | AL25: =IF($Z25="",0,IF($R25="",0,$R25)) -> 0 | AM25: =IF(OR($Z25="",$S25=""),0,$Z25*5%) -> 0 | AN25: =IF(OR($Z25="",$T25=""),0,$Z25*10%) -> 0 | AO25: =IF($Z25="",0,IF($U25="",0,$U25)) -> 0 | AP25: =SUM(AE25:AM25) -> 0
A26: 26 | C26: Enterprise connectors | D26: Enterprise Connectors Pipeline OnDemand Trigger | F26: Imp Team | G26: Faster Impl | H26: 3 | K26: 3 | L26: UnPlan | V26: =SUM(M26:U26) -> 0 | W26: =V26 - (V26 * (SUBSTITUTE(SUBSTITUTE($W$2, "Optimistic (", ""), "%)", "") / 100)) -> 0 | X26: =V26 + (W26 * (SUBSTITUTE(SUBSTITUTE($W$2, "Optimistic (", ""), "%)", "") / 100)) -> 0 | Y26: =(W26+(4*V26)+X26)/6 -> 0 | Z26: =Y26/2 -> 0 | AE26: =IF($Z26="",0,IF($M26="",0,$M26)) -> 0 | AF26: =IF(OR($Z26="",$N26=""),0,$Z26*5%) -> 0 | AG26: =IF(OR($Z26="",$O26=""),0,$Z26*10%) -> 0 | AH26: =IF($Z26="",0,IF(AND($P26="",$Q26=""),($Z26-$AE26-$AF26-$AG26-$AI26-$AK26-$AL26-$AM26-$AN26-$AO26),IF($P26="",0,IF($Q26="",($Z26-$AE26-$AF26-$AG26-$AI26-$AK26-$AL26-$AM26-$AN26-$AO26),($Z26-$AE26-$AF26-$AG26-$AI26-$AK26-$AL26-$AM26-$AN26-$AO26)*40%/(40%+15%))))) -> 0 | AI26: =IF($Z26="",0,IF($P26="",0,0.5)) -> 0 | AJ26: =IF($Z26="",0,IF(AND($P26="",$Q26=""),0,IF($Q26="",0,IF($P26="",($Z26-$AE26-$AF26-$AG26-$AI26-$AK26-$AL26-$AM26-$AN26-$AO26),($Z26-$AE26-$AF26-$AG26-$AI26-$AK26-$AL26-$AM26-$AN26-$AO26)*15%/(40%+15%))))) -> 0 | AK26: =IF($Z26="",0,$Z26*15%) -> 0 | AL26: =IF($Z26="",0,IF($R26="",0,$R26)) -> 0 | AM26: =IF(OR($Z26="",$S26=""),0,$Z26*5%) -> 0 | AN26: =IF(OR($Z26="",$T26=""),0,$Z26*10%) -> 0 | AO26: =IF($Z26="",0,IF($U26="",0,$U26)) -> 0 | AP26: =SUM(AE26:AM26) -> 0 | AQ26: In the meantime we should document the process of achieving that as project implementation
A27: 27 | D27: IT/OT Conversion for Enterprise Connectors (on hold) | F27: RnD | H27: 3 | K27: 1 | L27: UnPlan | V27: =SUM(M27:U27) -> 0 | W27: =V27 - (V27 * (SUBSTITUTE(SUBSTITUTE($W$2, "Optimistic (", ""), "%)", "") / 100)) -> 0 | X27: =V27 + (W27 * (SUBSTITUTE(SUBSTITUTE($W$2, "Optimistic (", ""), "%)", "") / 100)) -> 0 | Y27: =(W27+(4*V27)+X27)/6 -> 0 | Z27: =Y27/2 -> 0 | AE27: =IF($Z27="",0,IF($M27="",0,$M27)) -> 0 | AF27: =IF(OR($Z27="",$N27=""),0,$Z27*5%) -> 0 | AG27: =IF(OR($Z27="",$O27=""),0,$Z27*10%) -> 0 | AH27: =IF($Z27="",0,IF(AND($P27="",$Q27=""),($Z27-$AE27-$AF27-$AG27-$AI27-$AK27-$AL27-$AM27-$AN27-$AO27),IF($P27="",0,IF($Q27="",($Z27-$AE27-$AF27-$AG27-$AI27-$AK27-$AL27-$AM27-$AN27-$AO27),($Z27-$AE27-$AF27-$AG27-$AI27-$AK27-$AL27-$AM27-$AN27-$AO27)*40%/(40%+15%))))) -> 0 | AI27: =IF($Z27="",0,IF($P27="",0,0.5)) -> 0 | AJ27: =IF($Z27="",0,IF(AND($P27="",$Q27=""),0,IF($Q27="",0,IF($P27="",($Z27-$AE27-$AF27-$AG27-$AI27-$AK27-$AL27-$AM27-$AN27-$AO27),($Z27-$AE27-$AF27-$AG27-$AI27-$AK27-$AL27-$AM27-$AN27-$AO27)*15%/(40%+15%))))) -> 0 | AK27: =IF($Z27="",0,$Z27*15%) -> 0 | AL27: =IF($Z27="",0,IF($R27="",0,$R27)) -> 0 | AM27: =IF(OR($Z27="",$S27=""),0,$Z27*5%) -> 0 | AN27: =IF(OR($Z27="",$T27=""),0,$Z27*10%) -> 0 | AO27: =IF($Z27="",0,IF($U27="",0,$U27)) -> 0 | AP27: =SUM(AE27:AM27) -> 0
A28: 28 | C28: Calculated Tags Enhancement | D28: Nesting of Counter, Timer, Totalizer | E28: https://octopusdtlsupport.atlassian.net/browse/O2-697 | F28: RnD | H28: 1 | K28: 2 | L28: Plan | O28: 2 | P28: 20 | Q28: 15 | S28: 4 | T28: 25 | U28: =7+10+2 -> 19 | V28: =SUM(M28:U28) -> 85 | W28: =V28 - (V28 * (SUBSTITUTE(SUBSTITUTE($W$2, "Optimistic (", ""), "%)", "") / 100)) -> 42.5 | X28: =V28 + (W28 * (SUBSTITUTE(SUBSTITUTE($W$2, "Optimistic (", ""), "%)", "") / 100)) -> 106.25 | Y28: =(W28+(4*V28)+X28)/6 -> 81.458333 | Z28: =Y28/2 -> 40.729167 | AA28: 46146 | AB28: 46163 | AC28: 46164 | AD28: 46171 | AE28: =IF($Z28="",0,IF($M28="",0,$M28)) -> 0 | AF28: =IF(OR($Z28="",$N28=""),0,$Z28*5%) -> 0 | AG28: =IF(OR($Z28="",$O28=""),0,$Z28*10%) -> 4.0729167 | AH28: =IF($Z28="",0,IF(AND($P28="",$Q28=""),($Z28-$AE28-$AF28-$AG28-$AI28-$AK28-$AL28-$AM28-$AN28-$AO28),IF($P28="",0,IF($Q28="",($Z28-$AE28-$AF28-$AG28-$AI28-$AK28-$AL28-$AM28-$AN28-$AO28),($Z28-$AE28-$AF28-$AG28-$AI28-$AK28-$AL28-$AM28-$AN28-$AO28)*40%/(40%+15%))))) -> 3.5909091 | AI28: =IF($Z28="",0,IF($P28="",0,0.5)) -> 0.5 | AJ28: =IF($Z28="",0,IF(AND($P28="",$Q28=""),0,IF($Q28="",0,IF($P28="",($Z28-$AE28-$AF28-$AG28-$AI28-$AK28-$AL28-$AM28-$AN28-$AO28),($Z28-$AE28-$AF28-$AG28-$AI28-$AK28-$AL28-$AM28-$AN28-$AO28)*15%/(40%+15%))))) -> 1.3465909 | AK28: =IF($Z28="",0,$Z28*15%) -> 6.109375 | AL28: =IF($Z28="",0,IF($R28="",0,$R28)) -> 0 | AM28: =IF(OR($Z28="",$S28=""),0,$Z28*5%) -> 2.0364583 | AN28: =IF(OR($Z28="",$T28=""),0,$Z28*10%) -> 4.0729167 | AO28: =IF($Z28="",0,IF($U28="",0,$U28)) -> 19 | AP28: =SUM(AE28:AM28) -> 17.65625 | AQ28: Thought it was already done
A29: 29 | C29: Anomaly Detection Engine (ADE) | D29: ADE for Batch/BPM IT Data (Discussion Requried) | F29: RnD | H29: 2 | K29: 1+ | L29: UnPlan | W29: =V29 - (V29 * (SUBSTITUTE(SUBSTITUTE($W$2, "Optimistic (", ""), "%)", "") / 100)) -> 0 | X29: =V29 + (W29 * (SUBSTITUTE(SUBSTITUTE($W$2, "Optimistic (", ""), "%)", "") / 100)) -> 0 | Y29: =(W29+(4*V29)+X29)/6 -> 0 | Z29: =Y29/2 -> 0 | AE29: =IF($Z29="",0,IF($M29="",0,$M29)) -> 0 | AF29: =IF(OR($Z29="",$N29=""),0,$Z29*5%) -> 0 | AG29: =IF(OR($Z29="",$O29=""),0,$Z29*10%) -> 0 | AH29: =IF($Z29="",0,IF(AND($P29="",$Q29=""),($Z29-$AE29-$AF29-$AG29-$AI29-$AK29-$AL29-$AM29-$AN29-$AO29),IF($P29="",0,IF($Q29="",($Z29-$AE29-$AF29-$AG29-$AI29-$AK29-$AL29-$AM29-$AN29-$AO29),($Z29-$AE29-$AF29-$AG29-$AI29-$AK29-$AL29-$AM29-$AN29-$AO29)*40%/(40%+15%))))) -> 0 | AI29: =IF($Z29="",0,IF($P29="",0,0.5)) -> 0 | AJ29: =IF($Z29="",0,IF(AND($P29="",$Q29=""),0,IF($Q29="",0,IF($P29="",($Z29-$AE29-$AF29-$AG29-$AI29-$AK29-$AL29-$AM29-$AN29-$AO29),($Z29-$AE29-$AF29-$AG29-$AI29-$AK29-$AL29-$AM29-$AN29-$AO29)*15%/(40%+15%))))) -> 0 | AK29: =IF($Z29="",0,$Z29*15%) -> 0 | AL29: =IF($Z29="",0,IF($R29="",0,$R29)) -> 0 | AM29: =IF(OR($Z29="",$S29=""),0,$Z29*5%) -> 0 | AN29: =IF(OR($Z29="",$T29=""),0,$Z29*10%) -> 0 | AO29: =IF($Z29="",0,IF($U29="",0,$U29)) -> 0 | AP29: =SUM(AE29:AM29) -> 0
A30: 30 | D30: ADE for Enterprise Connectors IT Data (Discussion Required) | F30: RnD | L30: UnPlan | V30: =SUM(M30:U30) -> 0 | W30: =V30 - (V30 * (SUBSTITUTE(SUBSTITUTE($W$2, "Optimistic (", ""), "%)", "") / 100)) -> 0 | X30: =V30 + (W30 * (SUBSTITUTE(SUBSTITUTE($W$2, "Optimistic (", ""), "%)", "") / 100)) -> 0 | Y30: =(W30+(4*V30)+X30)/6 -> 0 | Z30: =Y30/2 -> 0 | AE30: =IF($Z30="",0,IF($M30="",0,$M30)) -> 0 | AF30: =IF(OR($Z30="",$N30=""),0,$Z30*5%) -> 0 | AG30: =IF(OR($Z30="",$O30=""),0,$Z30*10%) -> 0 | AH30: =IF($Z30="",0,IF(AND($P30="",$Q30=""),($Z30-$AE30-$AF30-$AG30-$AI30-$AK30-$AL30-$AM30-$AN30-$AO30),IF($P30="",0,IF($Q30="",($Z30-$AE30-$AF30-$AG30-$AI30-$AK30-$AL30-$AM30-$AN30-$AO30),($Z30-$AE30-$AF30-$AG30-$AI30-$AK30-$AL30-$AM30-$AN30-$AO30)*40%/(40%+15%))))) -> 0 | AI30: =IF($Z30="",0,IF($P30="",0,0.5)) -> 0 | AJ30: =IF($Z30="",0,IF(AND($P30="",$Q30=""),0,IF($Q30="",0,IF($P30="",($Z30-$AE30-$AF30-$AG30-$AI30-$AK30-$AL30-$AM30-$AN30-$AO30),($Z30-$AE30-$AF30-$AG30-$AI30-$AK30-$AL30-$AM30-$AN30-$AO30)*15%/(40%+15%))))) -> 0 | AK30: =IF($Z30="",0,$Z30*15%) -> 0 | AL30: =IF($Z30="",0,IF($R30="",0,$R30)) -> 0 | AM30: =IF(OR($Z30="",$S30=""),0,$Z30*5%) -> 0 | AN30: =IF(OR($Z30="",$T30=""),0,$Z30*10%) -> 0 | AO30: =IF($Z30="",0,IF($U30="",0,$U30)) -> 0 | AP30: =SUM(AE30:AM30) -> 0
A31: 31 | C31: Alarm | D31: Alarms for Batch IT Data | E31: https://octopusdtlsupport.atlassian.net/browse/O2-2277 | F31: RnD | H31: 1 | K31: 3 | L31: UnPlan | O31: 3 | P31: =(21+3) -> 24 | Q31: 5 | S31: 1 | T31: 5 | V31: =SUM(M31:U31) -> 38 | W31: =V31 - (V31 * (SUBSTITUTE(SUBSTITUTE($W$2, "Optimistic (", ""), "%)", "") / 100)) -> 19 | X31: =V31 + (W31 * (SUBSTITUTE(SUBSTITUTE($W$2, "Optimistic (", ""), "%)", "") / 100)) -> 47.5 | Y31: =(W31+(4*V31)+X31)/6 -> 36.416667 | Z31: =Y31/2 -> 18.208333 | AA31: 46121 | AB31: 46134 | AC31: 46135 | AD31: 46142 | AE31: =IF($Z31="",0,IF($M31="",0,$M31)) -> 0 | AF31: =IF(OR($Z31="",$N31=""),0,$Z31*5%) -> 0 | AG31: =IF(OR($Z31="",$O31=""),0,$Z31*10%) -> 1.8208333 | AH31: =IF($Z31="",0,IF(AND($P31="",$Q31=""),($Z31-$AE31-$AF31-$AG31-$AI31-$AK31-$AL31-$AM31-$AN31-$AO31),IF($P31="",0,IF($Q31="",($Z31-$AE31-$AF31-$AG31-$AI31-$AK31-$AL31-$AM31-$AN31-$AO31),($Z31-$AE31-$AF31-$AG31-$AI31-$AK31-$AL31-$AM31-$AN31-$AO31)*40%/(40%+15%))))) -> 7.5818182 | AI31: =IF($Z31="",0,IF($P31="",0,0.5)) -> 0.5 | AJ31: =IF($Z31="",0,IF(AND($P31="",$Q31=""),0,IF($Q31="",0,IF($P31="",($Z31-$AE31-$AF31-$AG31-$AI31-$AK31-$AL31-$AM31-$AN31-$AO31),($Z31-$AE31-$AF31-$AG31-$AI31-$AK31-$AL31-$AM31-$AN31-$AO31)*15%/(40%+15%))))) -> 2.8431818 | AK31: =IF($Z31="",0,$Z31*15%) -> 2.73125 | AL31: =IF($Z31="",0,IF($R31="",0,$R31)) -> 0 | AM31: =IF(OR($Z31="",$S31=""),0,$Z31*5%) -> 0.91041667 | AN31: =IF(OR($Z31="",$T31=""),0,$Z31*10%) -> 1.8208333 | AO31: =IF($Z31="",0,IF($U31="",0,$U31)) -> 0 | AP31: =SUM(AE31:AM31) -> 16.3875
D32: Alarms for BPM IT Data | E32: https://octopusdtlsupport.atlassian.net/browse/O2-2278 | F32: RnD | H32: 1 | K32: 3 | L32: UnPlan | O32: 6 | P32: =(21+6) -> 27 | Q32: 5 | S32: 1 | T32: 5 | V32: =SUM(M32:U32) -> 44 | W32: =V32 - (V32 * (SUBSTITUTE(SUBSTITUTE($W$2, "Optimistic (", ""), "%)", "") / 100)) -> 22 | X32: =V32 + (W32 * (SUBSTITUTE(SUBSTITUTE($W$2, "Optimistic (", ""), "%)", "") / 100)) -> 55 | Y32: =(W32+(4*V32)+X32)/6 -> 42.166667 | Z32: =Y32/2 -> 21.083333 | AA32: 46146 | AB32: 46167 | AC32: 46168 | AD32: 46175 | AE32: =IF($Z32="",0,IF($M32="",0,$M32)) -> 0 | AF32: =IF(OR($Z32="",$N32=""),0,$Z32*5%) -> 0 | AG32: =IF(OR($Z32="",$O32=""),0,$Z32*10%) -> 2.1083333 | AH32: =IF($Z32="",0,IF(AND($P32="",$Q32=""),($Z32-$AE32-$AF32-$AG32-$AI32-$AK32-$AL32-$AM32-$AN32-$AO32),IF($P32="",0,IF($Q32="",($Z32-$AE32-$AF32-$AG32-$AI32-$AK32-$AL32-$AM32-$AN32-$AO32),($Z32-$AE32-$AF32-$AG32-$AI32-$AK32-$AL32-$AM32-$AN32-$AO32)*40%/(40%+15%))))) -> 8.8363636 | AI32: =IF($Z32="",0,IF($P32="",0,0.5)) -> 0.5 | AJ32: =IF($Z32="",0,IF(AND($P32="",$Q32=""),0,IF($Q32="",0,IF($P32="",($Z32-$AE32-$AF32-$AG32-$AI32-$AK32-$AL32-$AM32-$AN32-$AO32),($Z32-$AE32-$AF32-$AG32-$AI32-$AK32-$AL32-$AM32-$AN32-$AO32)*15%/(40%+15%))))) -> 3.3136364 | AK32: =IF($Z32="",0,$Z32*15%) -> 3.1625 | AL32: =IF($Z32="",0,IF($R32="",0,$R32)) -> 0 | AM32: =IF(OR($Z32="",$S32=""),0,$Z32*5%) -> 1.0541667 | AN32: =IF(OR($Z32="",$T32=""),0,$Z32*10%) -> 2.1083333 | AO32: =IF($Z32="",0,IF($U32="",0,$U32)) -> 0 | AP32: =SUM(AE32:AM32) -> 18.975
A33: 32 | D33: Alarms for Enterprise Connectors IT Data SQL | E33: https://octopusdtlsupport.atlassian.net/browse/O2-2279 | F33: RnD | L33: UnPlan | O33: 3 | P33: =(12+3) -> 15 | Q33: 5 | T33: 5 | V33: =SUM(M33:U33) -> 28 | W33: =V33 - (V33 * (SUBSTITUTE(SUBSTITUTE($W$2, "Optimistic (", ""), "%)", "") / 100)) -> 14 | X33: =V33 + (W33 * (SUBSTITUTE(SUBSTITUTE($W$2, "Optimistic (", ""), "%)", "") / 100)) -> 35 | Y33: =(W33+(4*V33)+X33)/6 -> 26.833333 | Z33: =Y33/2 -> 13.416667 | AA33: 46169 | AB33: 46178 | AC33: 46181 | AD33: 46188 | AE33: =IF($Z33="",0,IF($M33="",0,$M33)) -> 0 | AF33: =IF(OR($Z33="",$N33=""),0,$Z33*5%) -> 0 | AG33: =IF(OR($Z33="",$O33=""),0,$Z33*10%) -> 1.3416667 | AH33: =IF($Z33="",0,IF(AND($P33="",$Q33=""),($Z33-$AE33-$AF33-$AG33-$AI33-$AK33-$AL33-$AM33-$AN33-$AO33),IF($P33="",0,IF($Q33="",($Z33-$AE33-$AF33-$AG33-$AI33-$AK33-$AL33-$AM33-$AN33-$AO33),($Z33-$AE33-$AF33-$AG33-$AI33-$AK33-$AL33-$AM33-$AN33-$AO33)*40%/(40%+15%))))) -> 5.9787879 | AI33: =IF($Z33="",0,IF($P33="",0,0.5)) -> 0.5 | AJ33: =IF($Z33="",0,IF(AND($P33="",$Q33=""),0,IF($Q33="",0,IF($P33="",($Z33-$AE33-$AF33-$AG33-$AI33-$AK33-$AL33-$AM33-$AN33-$AO33),($Z33-$AE33-$AF33-$AG33-$AI33-$AK33-$AL33-$AM33-$AN33-$AO33)*15%/(40%+15%))))) -> 2.2420455 | AK33: =IF($Z33="",0,$Z33*15%) -> 2.0125 | AL33: =IF($Z33="",0,IF($R33="",0,$R33)) -> 0 | AM33: =IF(OR($Z33="",$S33=""),0,$Z33*5%) -> 0 | AN33: =IF(OR($Z33="",$T33=""),0,$Z33*10%) -> 1.3416667 | AO33: =IF($Z33="",0,IF($U33="",0,$U33)) -> 0 | AP33: =SUM(AE33:AM33) -> 12.075
A34: 33 | D34: Alarms for Enterprise Connectors IT Data Rest API | E34: https://octopusdtlsupport.atlassian.net/browse/O2-2280 | F34: RnD | O34: 3 | P34: =(12+3) -> 15 | Q34: 5 | T34: 5 | V34: =SUM(M34:U34) -> 28 | W34: =V34 - (V34 * (SUBSTITUTE(SUBSTITUTE($W$2, "Optimistic (", ""), "%)", "") / 100)) -> 14 | X34: =V34 + (W34 * (SUBSTITUTE(SUBSTITUTE($W$2, "Optimistic (", ""), "%)", "") / 100)) -> 35 | Y34: =(W34+(4*V34)+X34)/6 -> 26.833333 | Z34: =Y34/2 -> 13.416667 | AA34: 46182 | AB34: 46191 | AC34: 46192 | AD34: 46199 | AE34: =IF($Z34="",0,IF($M34="",0,$M34)) -> 0 | AF34: =IF(OR($Z34="",$N34=""),0,$Z34*5%) -> 0 | AG34: =IF(OR($Z34="",$O34=""),0,$Z34*10%) -> 1.3416667 | AH34: =IF($Z34="",0,IF(AND($P34="",$Q34=""),($Z34-$AE34-$AF34-$AG34-$AI34-$AK34-$AL34-$AM34-$AN34-$AO34),IF($P34="",0,IF($Q34="",($Z34-$AE34-$AF34-$AG34-$AI34-$AK34-$AL34-$AM34-$AN34-$AO34),($Z34-$AE34-$AF34-$AG34-$AI34-$AK34-$AL34-$AM34-$AN34-$AO34)*40%/(40%+15%))))) -> 5.9787879 | AI34: =IF($Z34="",0,IF($P34="",0,0.5)) -> 0.5 | AJ34: =IF($Z34="",0,IF(AND($P34="",$Q34=""),0,IF($Q34="",0,IF($P34="",($Z34-$AE34-$AF34-$AG34-$AI34-$AK34-$AL34-$AM34-$AN34-$AO34),($Z34-$AE34-$AF34-$AG34-$AI34-$AK34-$AL34-$AM34-$AN34-$AO34)*15%/(40%+15%))))) -> 2.2420455 | AK34: =IF($Z34="",0,$Z34*15%) -> 2.0125 | AL34: =IF($Z34="",0,IF($R34="",0,$R34)) -> 0 | AM34: =IF(OR($Z34="",$S34=""),0,$Z34*5%) -> 0 | AN34: =IF(OR($Z34="",$T34=""),0,$Z34*10%) -> 1.3416667 | AO34: =IF($Z34="",0,IF($U34="",0,$U34)) -> 0 | AP34: =SUM(AE34:AM34) -> 12.075
A35: 34 | D35: Alarms for Enterprise Connectors IT Data SFTP | E35: https://octopusdtlsupport.atlassian.net/browse/O2-2296 | F35: RnD | O35: 3 | P35: =(12+3) -> 15 | Q35: 5 | T35: 5 | V35: =SUM(M35:U35) -> 28 | W35: =V35 - (V35 * (SUBSTITUTE(SUBSTITUTE($W$2, "Optimistic (", ""), "%)", "") / 100)) -> 14 | X35: =V35 + (W35 * (SUBSTITUTE(SUBSTITUTE($W$2, "Optimistic (", ""), "%)", "") / 100)) -> 35 | Y35: =(W35+(4*V35)+X35)/6 -> 26.833333 | Z35: =Y35/2 -> 13.416667 | AA35: 46195 | AB35: 46204 | AC35: 46205 | AD35: 46212 | AE35: =IF($Z35="",0,IF($M35="",0,$M35)) -> 0 | AF35: =IF(OR($Z35="",$N35=""),0,$Z35*5%) -> 0 | AG35: =IF(OR($Z35="",$O35=""),0,$Z35*10%) -> 1.3416667 | AH35: =IF($Z35="",0,IF(AND($P35="",$Q35=""),($Z35-$AE35-$AF35-$AG35-$AI35-$AK35-$AL35-$AM35-$AN35-$AO35),IF($P35="",0,IF($Q35="",($Z35-$AE35-$AF35-$AG35-$AI35-$AK35-$AL35-$AM35-$AN35-$AO35),($Z35-$AE35-$AF35-$AG35-$AI35-$AK35-$AL35-$AM35-$AN35-$AO35)*40%/(40%+15%))))) -> 5.9787879 | AI35: =IF($Z35="",0,IF($P35="",0,0.5)) -> 0.5 | AJ35: =IF($Z35="",0,IF(AND($P35="",$Q35=""),0,IF($Q35="",0,IF($P35="",($Z35-$AE35-$AF35-$AG35-$AI35-$AK35-$AL35-$AM35-$AN35-$AO35),($Z35-$AE35-$AF35-$AG35-$AI35-$AK35-$AL35-$AM35-$AN35-$AO35)*15%/(40%+15%))))) -> 2.2420455 | AK35: =IF($Z35="",0,$Z35*15%) -> 2.0125 | AL35: =IF($Z35="",0,IF($R35="",0,$R35)) -> 0 | AM35: =IF(OR($Z35="",$S35=""),0,$Z35*5%) -> 0 | AN35: =IF(OR($Z35="",$T35=""),0,$Z35*10%) -> 1.3416667 | AO35: =IF($Z35="",0,IF($U35="",0,$U35)) -> 0 | AP35: =SUM(AE35:AM35) -> 12.075
A36: 35 | D36: Alarms for Enterprise Connectors IT Data SAP | E36: https://octopusdtlsupport.atlassian.net/browse/O2-2321 | F36: RnD | O36: 3 | P36: =(12+3) -> 15 | Q36: 5 | T36: 5 | V36: =SUM(M36:U36) -> 28 | W36: =V36 - (V36 * (SUBSTITUTE(SUBSTITUTE($W$2, "Optimistic (", ""), "%)", "") / 100)) -> 14 | X36: =V36 + (W36 * (SUBSTITUTE(SUBSTITUTE($W$2, "Optimistic (", ""), "%)", "") / 100)) -> 35 | Y36: =(W36+(4*V36)+X36)/6 -> 26.833333 | Z36: =Y36/2 -> 13.416667 | AA36: 46206 | AB36: 46217 | AC36: 46218 | AD36: 46225 | AE36: =IF($Z36="",0,IF($M36="",0,$M36)) -> 0 | AF36: =IF(OR($Z36="",$N36=""),0,$Z36*5%) -> 0 | AG36: =IF(OR($Z36="",$O36=""),0,$Z36*10%) -> 1.3416667 | AH36: =IF($Z36="",0,IF(AND($P36="",$Q36=""),($Z36-$AE36-$AF36-$AG36-$AI36-$AK36-$AL36-$AM36-$AN36-$AO36),IF($P36="",0,IF($Q36="",($Z36-$AE36-$AF36-$AG36-$AI36-$AK36-$AL36-$AM36-$AN36-$AO36),($Z36-$AE36-$AF36-$AG36-$AI36-$AK36-$AL36-$AM36-$AN36-$AO36)*40%/(40%+15%))))) -> 5.9787879 | AI36: =IF($Z36="",0,IF($P36="",0,0.5)) -> 0.5 | AJ36: =IF($Z36="",0,IF(AND($P36="",$Q36=""),0,IF($Q36="",0,IF($P36="",($Z36-$AE36-$AF36-$AG36-$AI36-$AK36-$AL36-$AM36-$AN36-$AO36),($Z36-$AE36-$AF36-$AG36-$AI36-$AK36-$AL36-$AM36-$AN36-$AO36)*15%/(40%+15%))))) -> 2.2420455 | AK36: =IF($Z36="",0,$Z36*15%) -> 2.0125 | AL36: =IF($Z36="",0,IF($R36="",0,$R36)) -> 0 | AM36: =IF(OR($Z36="",$S36=""),0,$Z36*5%) -> 0 | AN36: =IF(OR($Z36="",$T36=""),0,$Z36*10%) -> 1.3416667 | AO36: =IF($Z36="",0,IF($U36="",0,$U36)) -> 0 | AP36: =SUM(AE36:AM36) -> 12.075
A37: 36 | C37: Diagnostics | D37: ML based Tier 4 Diagnostics (Landing Pattern based alerts) | F37: RnD | H37: 1 | L37: UnPlan | P37: 4 | Q37: 3 | S37: 1 | V37: =SUM(M37:U37) -> 8 | W37: =V37 - (V37 * (SUBSTITUTE(SUBSTITUTE($W$2, "Optimistic (", ""), "%)", "") / 100)) -> 4 | X37: =V37 + (W37 * (SUBSTITUTE(SUBSTITUTE($W$2, "Optimistic (", ""), "%)", "") / 100)) -> 10 | Y37: =(W37+(4*V37)+X37)/6 -> 7.6666667 | Z37: =Y37/2 -> 3.8333333 | AE37: =IF($Z37="",0,IF($M37="",0,$M37)) -> 0 | AF37: =IF(OR($Z37="",$N37=""),0,$Z37*5%) -> 0 | AG37: =IF(OR($Z37="",$O37=""),0,$Z37*10%) -> 0 | AH37: =IF($Z37="",0,IF(AND($P37="",$Q37=""),($Z37-$AE37-$AF37-$AG37-$AI37-$AK37-$AL37-$AM37-$AN37-$AO37),IF($P37="",0,IF($Q37="",($Z37-$AE37-$AF37-$AG37-$AI37-$AK37-$AL37-$AM37-$AN37-$AO37),($Z37-$AE37-$AF37-$AG37-$AI37-$AK37-$AL37-$AM37-$AN37-$AO37)*40%/(40%+15%))))) -> 1.8666667 | AI37: =IF($Z37="",0,IF($P37="",0,0.5)) -> 0.5 | AJ37: =IF($Z37="",0,IF(AND($P37="",$Q37=""),0,IF($Q37="",0,IF($P37="",($Z37-$AE37-$AF37-$AG37-$AI37-$AK37-$AL37-$AM37-$AN37-$AO37),($Z37-$AE37-$AF37-$AG37-$AI37-$AK37-$AL37-$AM37-$AN37-$AO37)*15%/(40%+15%))))) -> 0.7 | AK37: =IF($Z37="",0,$Z37*15%) -> 0.575 | AL37: =IF($Z37="",0,IF($R37="",0,$R37)) -> 0 | AM37: =IF(OR($Z37="",$S37=""),0,$Z37*5%) -> 0.19166667 | AN37: =IF(OR($Z37="",$T37=""),0,$Z37*10%) -> 0 | AO37: =IF($Z37="",0,IF($U37="",0,$U37)) -> 0 | AP37: =SUM(AE37:AM37) -> 3.8333333
A38: 37 | C38: OmniOEE | D38: OmniOEE Phase 1 - Batch/BPM Std Compute Module (Curated, Library-stored) | F38: Management | H38: 3 | K38: 1 | L38: UnPlan | V38: =SUM(M38:U38) -> 0 | W38: =V38 - (V38 * (SUBSTITUTE(SUBSTITUTE($W$2, "Optimistic (", ""), "%)", "") / 100)) -> 0 | X38: =V38 + (W38 * (SUBSTITUTE(SUBSTITUTE($W$2, "Optimistic (", ""), "%)", "") / 100)) -> 0 | Y38: =(W38+(4*V38)+X38)/6 -> 0 | Z38: =Y38/2 -> 0 | AE38: =IF($Z38="",0,IF($M38="",0,$M38)) -> 0 | AF38: =IF(OR($Z38="",$N38=""),0,$Z38*5%) -> 0 | AG38: =IF(OR($Z38="",$O38=""),0,$Z38*10%) -> 0 | AH38: =IF($Z38="",0,IF(AND($P38="",$Q38=""),($Z38-$AE38-$AF38-$AG38-$AI38-$AK38-$AL38-$AM38-$AN38-$AO38),IF($P38="",0,IF($Q38="",($Z38-$AE38-$AF38-$AG38-$AI38-$AK38-$AL38-$AM38-$AN38-$AO38),($Z38-$AE38-$AF38-$AG38-$AI38-$AK38-$AL38-$AM38-$AN38-$AO38)*40%/(40%+15%))))) -> 0 | AI38: =IF($Z38="",0,IF($P38="",0,0.5)) -> 0 | AJ38: =IF($Z38="",0,IF(AND($P38="",$Q38=""),0,IF($Q38="",0,IF($P38="",($Z38-$AE38-$AF38-$AG38-$AI38-$AK38-$AL38-$AM38-$AN38-$AO38),($Z38-$AE38-$AF38-$AG38-$AI38-$AK38-$AL38-$AM38-$AN38-$AO38)*15%/(40%+15%))))) -> 0 | AK38: =IF($Z38="",0,$Z38*15%) -> 0 | AL38: =IF($Z38="",0,IF($R38="",0,$R38)) -> 0 | AM38: =IF(OR($Z38="",$S38=""),0,$Z38*5%) -> 0 | AN38: =IF(OR($Z38="",$T38=""),0,$Z38*10%) -> 0 | AO38: =IF($Z38="",0,IF($U38="",0,$U38)) -> 0 | AP38: =SUM(AE38:AM38) -> 0 | AQ38: Need to understand it. Also we should be able to document this and do it as project
A39: 38 | D39: OmniOEE Phase 2 – Full OEE System (Production Planning, Configuration, Data, Visualizations) | F39: Management | H39: 3 | K39: 2 | L39: UnPlan | W39: =V39 - (V39 * (SUBSTITUTE(SUBSTITUTE($W$2, "Optimistic (", ""), "%)", "") / 100)) -> 0 | X39: =V39 + (W39 * (SUBSTITUTE(SUBSTITUTE($W$2, "Optimistic (", ""), "%)", "") / 100)) -> 0 | Y39: =(W39+(4*V39)+X39)/6 -> 0 | Z39: =Y39/2 -> 0 | AE39: =IF($Z39="",0,IF($M39="",0,$M39)) -> 0 | AF39: =IF(OR($Z39="",$N39=""),0,$Z39*5%) -> 0 | AG39: =IF(OR($Z39="",$O39=""),0,$Z39*10%) -> 0 | AH39: =IF($Z39="",0,IF(AND($P39="",$Q39=""),($Z39-$AE39-$AF39-$AG39-$AI39-$AK39-$AL39-$AM39-$AN39-$AO39),IF($P39="",0,IF($Q39="",($Z39-$AE39-$AF39-$AG39-$AI39-$AK39-$AL39-$AM39-$AN39-$AO39),($Z39-$AE39-$AF39-$AG39-$AI39-$AK39-$AL39-$AM39-$AN39-$AO39)*40%/(40%+15%))))) -> 0 | AI39: =IF($Z39="",0,IF($P39="",0,0.5)) -> 0 | AJ39: =IF($Z39="",0,IF(AND($P39="",$Q39=""),0,IF($Q39="",0,IF($P39="",($Z39-$AE39-$AF39-$AG39-$AI39-$AK39-$AL39-$AM39-$AN39-$AO39),($Z39-$AE39-$AF39-$AG39-$AI39-$AK39-$AL39-$AM39-$AN39-$AO39)*15%/(40%+15%))))) -> 0 | AK39: =IF($Z39="",0,$Z39*15%) -> 0 | AL39: =IF($Z39="",0,IF($R39="",0,$R39)) -> 0 | AM39: =IF(OR($Z39="",$S39=""),0,$Z39*5%) -> 0 | AN39: =IF(OR($Z39="",$T39=""),0,$Z39*10%) -> 0 | AO39: =IF($Z39="",0,IF($U39="",0,$U39)) -> 0 | AP39: =SUM(AE39:AM39) -> 0
A40: 39 | C40: OmniALA | D40: Aux Load Advisor | F40: Management | H40: 3 | K40: 1 | L40: UnPlan | O40: 10 | V40: =SUM(M40:U40) -> 10 | W40: =V40 - (V40 * (SUBSTITUTE(SUBSTITUTE($W$2, "Optimistic (", ""), "%)", "") / 100)) -> 5 | X40: =V40 + (W40 * (SUBSTITUTE(SUBSTITUTE($W$2, "Optimistic (", ""), "%)", "") / 100)) -> 12.5 | Y40: =(W40+(4*V40)+X40)/6 -> 9.5833333 | Z40: =Y40/2 -> 4.7916667 | AE40: =IF($Z40="",0,IF($M40="",0,$M40)) -> 0 | AF40: =IF(OR($Z40="",$N40=""),0,$Z40*5%) -> 0 | AG40: =IF(OR($Z40="",$O40=""),0,$Z40*10%) -> 0.47916667 | AH40: =IF($Z40="",0,IF(AND($P40="",$Q40=""),($Z40-$AE40-$AF40-$AG40-$AI40-$AK40-$AL40-$AM40-$AN40-$AO40),IF($P40="",0,IF($Q40="",($Z40-$AE40-$AF40-$AG40-$AI40-$AK40-$AL40-$AM40-$AN40-$AO40),($Z40-$AE40-$AF40-$AG40-$AI40-$AK40-$AL40-$AM40-$AN40-$AO40)*40%/(40%+15%))))) -> 3.59375 | AI40: =IF($Z40="",0,IF($P40="",0,0.5)) -> 0 | AJ40: =IF($Z40="",0,IF(AND($P40="",$Q40=""),0,IF($Q40="",0,IF($P40="",($Z40-$AE40-$AF40-$AG40-$AI40-$AK40-$AL40-$AM40-$AN40-$AO40),($Z40-$AE40-$AF40-$AG40-$AI40-$AK40-$AL40-$AM40-$AN40-$AO40)*15%/(40%+15%))))) -> 0 | AK40: =IF($Z40="",0,$Z40*15%) -> 0.71875 | AL40: =IF($Z40="",0,IF($R40="",0,$R40)) -> 0 | AM40: =IF(OR($Z40="",$S40=""),0,$Z40*5%) -> 0 | AN40: =IF(OR($Z40="",$T40=""),0,$Z40*10%) -> 0 | AO40: =IF($Z40="",0,IF($U40="",0,$U40)) -> 0 | AP40: =SUM(AE40:AM40) -> 4.7916667 | AQ40: Document and make it sound as a product till we get an order
...

Sheet Sheet6
C1: Man days
B2: Most likely | C2: 20 | D2: =C2*3 -> 60
B3: 0.3 | C3: =C2*1.3 -> 26 | D3: =C3 -> 26
C4: =C2/1.5 -> 13.333333 | D4: =C4 -> 13.333333
D5: =SUM(D2:D4) -> 99.333333
D6: =D5/6 -> 16.555556

Sheet Fintech Fuel RMI
A1: Fintech Fuel Roadmap Items | H1: BHW | I1: TK | J1: AA | K1: TS | M1: RnD Most likely | W1: TK Budgeted
A2: Sr # | B2: Category | C2: Components | D2: Road Map Items | E2: JIRA ID | F2: Originator | G2: Value | H2: Priority | I2: Priority | J2: Priority | K2: Priority | L2: Plan Status | M2: Prc Design | N2: R/URS | O2: R/DDS | P2: Dev | Q2: SQA | R2: Prc Test | S2: Doc | T2: Reg SQA | U2: Release | V2: Man Days | W2: ="Optimistic ("&Summary!E7&")" -> Optimistic (50%) | X2: Pessimistic (10%) | Y2: Est Formula | Z2: TK's TARGET | AA2: Start Date | AB2: Dev End | AC2: SQA HO | AD2: Prod Date | AE2: Prc Design | AF2: R/URS (5%) | AG2: R/DDS (10%) | AH2: Dev (40%) | AI2: Handover | AJ2: SQA (15%) | AK2: Bug Fixing (15%) | AL2: Prc Test | AM2: Doc (5%) | AN2: Reg SQA (10%) | AO2: Release
A3: 1 | B3: Input | C3: Alsons | D3: Alsons Connectivity for Reading (done) (6h) | F3: PGL | N3: 2 | O3: 1 | P3: 5 | Q3: 0 | S3: 0 | U3: 2 | V3: =SUM(M3:U3) -> 10 | W3: =V3 - (V3 * (SUBSTITUTE(SUBSTITUTE($W$2, "Optimistic (", ""), "%)", "") / 100)) -> 5 | X3: =V3 + (V3 * (SUBSTITUTE(SUBSTITUTE($X$2, "Pessimistic (", ""), "%)", "") / 100)) -> 11 | Y3: =(W3+(4*V3)+X3)/6 -> 9.3333333 | Z3: =Y3/2 -> 4.6666667 | AE3: =IF($Z3="",0,IF($M3="",0,$M3)) -> 0 | AF3: =IF(OR($Z3="",$N3=""),0,$Z3*5%) -> 0.23333333 | AG3: =IF(OR($Z3="",$O3=""),0,$Z3*10%) -> 0.46666667 | AH3: =IF($Z3="",0,IF(AND($P3="",$Q3=""),($Z3-$AE3-$AF3-$AG3-$AI3-$AK3-$AL3-$AM3-$AN3-$AO3),IF($P3="",0,IF($Q3="",($Z3-$AE3-$AF3-$AG3-$AI3-$AK3-$AL3-$AM3-$AN3-$AO3),($Z3-$AE3-$AF3-$AG3-$AI3-$AK3-$AL3-$AM3-$AN3-$AO3)*40%/(40%+15%))))) -> 0.38787879 | AI3: =IF($Z3="",0,IF($P3="",0,0.5)) -> 0.5 | AJ3: =IF($Z3="",0,IF(AND($P3="",$Q3=""),0,IF($Q3="",0,IF($P3="",($Z3-$AE3-$AF3-$AG3-$AI3-$AK3-$AL3-$AM3-$AN3-$AO3),($Z3-$AE3-$AF3-$AG3-$AI3-$AK3-$AL3-$AM3-$AN3-$AO3)*15%/(40%+15%))))) -> 0.14545455 | AK3: =IF($Z3="",0,$Z3*15%) -> 0.7 | AL3: =IF($Z3="",0,IF($R3="",0,$R3)) -> 0 | AM3: =IF(OR($Z3="",$S3=""),0,$Z3*5%) -> 0.23333333 | AN3: =IF(OR($Z3="",$T3=""),0,$Z3*10%) -> 0 | AO3: =IF($Z3="",0,IF($U3="",0,$U3)) -> 2
